Workbook

Sheet hipblaslt_mi300x_GF
B1: M | C1: N | D1: K | E1: mul | F1: acc | G1: scale | H1: n_iter | I1: n_thread | J1: n_wg | K1: n_wf | L1: wf_size | M1: wg_size | N1: n_flops | O1: n_bytes | P1: time_ms | Q1: gflop/s | R1: avg_clock | S1: max_clock | T1: min_clock | U1: stdev_clock
A2: =B2&"-"&C2&"-"&D2&"-"&E2&"-"&F2&"-"&G2 -> 4096-1-4096-fp16-fp32-fp32 | B2: 4096 | C2: 1 | D2: 4096 | E2: fp16 | F2: fp32 | G2: fp32 | H2: 524288 | I2: 0 | J2: 0 | K2: 0 | L2: 64 | M2: 0 | N2: 17592186044416 | O2: 35210141892608 | P2: 17678.85 | Q2: 995.1 | R2: 0 | S2: 0 | T2: 0 | U2: 0
A3: =B3&"-"&C3&"-"&D3&"-"&E3&"-"&F3&"-"&G3 -> 4096-1-4096-bf8-fp16-fp32 | B3: 4096 | C3: 1 | D3: 4096 | E3: bf8 | F3: fp16 | G3: fp32 | H3: 524288 | I3: 0 | J3: 0 | K3: 0 | L3: 64 | M3: 0 | N3: 17592186044416 | O3: 17605070946304 | P3: 22164.97 | Q3: 793.69 | R3: 0 | S3: 0 | T3: 0 | U3: 0
A4: =B4&"-"&C4&"-"&D4&"-"&E4&"-"&F4&"-"&G4 -> 8192-1-8192-fp32-fp32-fp32 | B4: 8192 | C4: 1 | D4: 8192 | E4: fp32 | F4: fp32 | G4: fp32 | H4: 524288 | I4: 0 | J4: 0 | K4: 0 | L4: 64 | M4: 0 | N4: 70368744177664 | O4: 281543696187392 | P4: 73993.87 | Q4: 951.01 | R4: 0 | S4: 0 | T4: 0 | U4: 0
A5: =B5&"-"&C5&"-"&D5&"-"&E5&"-"&F5&"-"&G5 -> 8192-1-8192-fp16-fp16-fp32 | B5: 8192 | C5: 1 | D5: 8192 | E5: fp16 | F5: fp16 | G5: fp32 | H5: 524288 | I5: 0 | J5: 0 | K5: 0 | L5: 64 | M5: 0 | N5: 70368744177664 | O5: 140771848093696 | P5: 31093.84 | Q5: 2263.11 | R5: 0 | S5: 0 | T5: 0 | U5: 0
A6: =B6&"-"&C6&"-"&D6&"-"&E6&"-"&F6&"-"&G6 -> 8192-1-8192-fp8-fp32-fp32 | B6: 8192 | C6: 1 | D6: 8192 | E6: fp8 | F6: fp32 | G6: fp32 | H6: 524288 | I6: 0 | J6: 0 | K6: 0 | L6: 64 | M6: 0 | N6: 70368744177664 | O6: 70411693850624 | P6: 54715.69 | Q6: 1286.08 | R6: 0 | S6: 0 | T6: 0 | U6: 0
A7: =B7&"-"&C7&"-"&D7&"-"&E7&"-"&F7&"-"&G7 -> 65536-1-65536-tf32-fp32-fp32 | B7: 65536 | C7: 1 | D7: 65536 | E7: tf32 | F7: fp32 | G7: fp32 | H7: 32768 | I7: 0 | J7: 0 | K7: 0 | L7: 64 | M7: 0 | N7: 281474976710656 | O7: 1.1259343e+15 | P7: 280048.53 | Q7: 1005.09 | R7: 0 | S7: 0 | T7: 0 | U7: 0
A8: =B8&"-"&C8&"-"&D8&"-"&E8&"-"&F8&"-"&G8 -> 4096-1-4096-fp64-fp64-fp64 | B8: 4096 | C8: 1 | D8: 4096 | E8: fp64 | F8: fp64 | G8: fp64 | H8: 524288 | I8: 0 | J8: 0 | K8: 0 | L8: 64 | M8: 0 | N8: 17592186044416 | O8: 140806207832064 | P8: 9210.55 | Q8: 1910 | R8: 0 | S8: 0 | T8: 0 | U8: 0
A9: =B9&"-"&C9&"-"&D9&"-"&E9&"-"&F9&"-"&G9 -> 16384-1-16384-fp64-fp64-fp64 | B9: 16384 | C9: 1 | D9: 16384 | E9: fp64 | F9: fp64 | G9: fp64 | H9: 131072 | I9: 0 | J9: 0 | K9: 0 | L9: 64 | M9: 0 | N9: 70368744177664 | O9: 563018672898048 | P9: 2360.51 | Q9: 29810.83 | R9: 0 | S9: 0 | T9: 0 | U9: 0
A10: =B10&"-"&C10&"-"&D10&"-"&E10&"-"&F10&"-"&G10 -> 32768-1-32768-bf16-fp32-fp32 | B10: 32768 | C10: 1 | D10: 32768 | E10: bf16 | F10: fp32 | G10: fp32 | H10: 65536 | I10: 0 | J10: 0 | K10: 0 | L10: 64 | M10: 0 | N10: 140737488355328 | O10: 281500746514432 | P10: 36642.7 | Q10: 3840.81 | R10: 0 | S10: 0 | T10: 0 | U10: 0
A11: =B11&"-"&C11&"-"&D11&"-"&E11&"-"&F11&"-"&G11 -> 8192-1-8192-fp16-fp32-fp32 | B11: 8192 | C11: 1 | D11: 8192 | E11: fp16 | F11: fp32 | G11: fp32 | H11: 524288 | I11: 0 | J11: 0 | K11: 0 | L11: 64 | M11: 0 | N11: 70368744177664 | O11: 140789027962880 | P11: 30867.17 | Q11: 2279.73 | R11: 0 | S11: 0 | T11: 0 | U11: 0
A12: =B12&"-"&C12&"-"&D12&"-"&E12&"-"&F12&"-"&G12 -> 98304-1-98304-int8-int32-int32 | B12: 98304 | C12: 1 | D12: 98304 | E12: int8 | F12: int32 | G12: int32 | H12: 32768 | I12: 0 | J12: 0 | K12: 0 | L12: 64 | M12: 0 | N12: 633318697598976 | O12: 633350909853696 | P12: 175573.48 | Q12: 3607.14 | R12: 0 | S12: 0 | T12: 0 | U12: 0
A13: =B13&"-"&C13&"-"&D13&"-"&E13&"-"&F13&"-"&G13 -> 16384-1-16384-fp32-fp32-fp32 | B13: 16384 | C13: 1 | D13: 16384 | E13: fp32 | F13: fp32 | G13: fp32 | H13: 131072 | I13: 0 | J13: 0 | K13: 0 | L13: 64 | M13: 0 | N13: 70368744177664 | O13: 281509336449024 | P13: 51130.84 | Q13: 1376.25 | R13: 0 | S13: 0 | T13: 0 | U13: 0
... A26: =B26&"-"&C26&"-"&D26&"-"&E26&"-"&F26&"-"&G26 -> 4096-1-4096-fp8-fp8-fp32 | B26: 4096 | C26: 1 | D26: 4096 | E26: fp8 | F26: fp8 | G26: fp32 | H26: 524288 | I26: 0 | J26: 0 | K26: 0 | L26: 64 | M26: 0 | N26: 17592186044416 | O26: 17600775979008 | P26: 22451.72 | Q26: 783.56 | R26: 0 | S26: 0 | T26: 0 | U26: 0
A27: =B27&"-"&C27&"-"&D27&"-"&E27&"-"&F27&"-"&G27 -> 65536-1-65536-fp16-fp16-fp16 | B27: 65536 | C27: 1 | D27: 65536 | E27: fp16 | F27: fp16 | G27: fp16
A28: =B28&"-"&C28&"-"&D28&"-"&E28&"-"&F28&"-"&G28 -> 16384-1-16384-bf8-fp32-fp32 | B28: 16384 | C28: 1 | D28: 16384 | E28: bf8 | F28: fp32 | G28: fp32 | H28: 131072 | I28: 0 | J28: 0 | K28: 0 | L28: 64 | M28: 0 | N28: 70368744177664 | O28: 70390219014144 | P28: 54850.2 | Q28: 1282.93 | R28: 0 | S28: 0 | T28: 0 | U28: 0
A29: =B29&"-"&C29&"-"&D29&"-"&E29&"-"&F29&"-"&G29 -> 8192-1-8192-tf32-fp32-fp32 | B29: 8192 | C29: 1 | D29: 8192 | E29: tf32 | F29: fp32 | G29: fp32 | H29: 524288 | I29: 0 | J29: 0 | K29: 0 | L29: 64 | M29: 0 | N29: 70368744177664 | O29: 281543696187392 | P29: 77424.27 | Q29: 908.87 | R29: 0 | S29: 0 | T29: 0 | U29: 0
A30: =B30&"-"&C30&"-"&D30&"-"&E30&"-"&F30&"-"&G30 -> 4096-1-4096-tf32-fp32-fp32 | B30: 4096 | C30: 1 | D30: 4096 | E30: tf32 | F30: fp32 | G30: fp32 | H30: 524288 | I30: 0 | J30: 0 | K30: 0 | L30: 64 | M30: 0 | N30: 17592186044416 | O30: 70403103916032 | P30: 37597.23 | Q30: 467.91 | R30: 0 | S30: 0 | T30: 0 | U30: 0
A31: =B31&"-"&C31&"-"&D31&"-"&E31&"-"&F31&"-"&G31 -> 4096-1-4096-fp16-fp16-fp16 | B31: 4096 | C31: 1 | D31: 4096 | E31: fp16 | F31: fp16 | G31: fp16
A32: =B32&"-"&C32&"-"&D32&"-"&E32&"-"&F32&"-"&G32 -> 16384-1-16384-fp16-fp16-fp16 | B32: 16384 | C32: 1 | D32: 16384 | E32: fp16 | F32: fp16 | G32: fp16
A33: =B33&"-"&C33&"-"&D33&"-"&E33&"-"&F33&"-"&G33 -> 8192-1-8192-fp8-fp8-fp32 | B33: 8192 | C33: 1 | D33: 8192 | E33: fp8 | F33: fp8 | G33: fp32 | H33: 524288 | I33: 0 | J33: 0 | K33: 0 | L33: 64 | M33: 0 | N33: 70368744177664 | O33: 70385924046848 | P33: 54935.76 | Q33: 1280.93 | R33: 0 | S33: 0 | T33: 0 | U33: 0
A34: =B34&"-"&C34&"-"&D34&"-"&E34&"-"&F34&"-"&G34 -> 65536-1-65536-fp16-fp32-fp32 | B34: 65536 | C34: 1 | D34: 65536 | E34: fp16 | F34: fp32 | G34: fp32 | H34: 32768 | I34: 0 | J34: 0 | K34: 0 | L34: 64 | M34: 0 | N34: 281474976710656 | O34: 562975723225088 | P34: 65562.38 | Q34: 4293.24 | R34: 0 | S34: 0 | T34: 0 | U34: 0
A35: =B35&"-"&C35&"-"&D35&"-"&E35&"-"&F35&"-"&G35 -> 98304-1-98304-bf8-bf8-fp32 | B35: 98304 | C35: 1 | D35: 98304 | E35: bf8 | F35: bf8 | G35: fp32 | H35: 32768 | I35: 0 | J35: 0 | K35: 0 | L35: 64 | M35: 0 | N35: 633318697598976 | O35: 633331582500864 | P35: 444869.5 | Q35: 1423.61 | R35: 0 | S35: 0 | T35: 0 | U35: 0
A36: =B36&"-"&C36&"-"&D36&"-"&E36&"-"&F36&"-"&G36 -> 16384-1-16384-bf16-fp32-fp32 | B36: 16384 | C36: 1 | D36: 16384 | E36: bf16 | F36: fp32 | G36: fp32 | H36: 131072 | I36: 0 | J36: 0 | K36: 0 | L36: 64 | M36: 0 | N36: 70368744177664 | O36: 140763258159104 | P36: 18882 | Q36: 3726.76 | R36: 0 | S36: 0 | T36: 0 | U36: 0
A37: =B37&"-"&C37&"-"&D37&"-"&E37&"-"&F37&"-"&G37 -> 8192-1-8192-fp8-fp16-fp32 | B37: 8192 | C37: 1 | D37: 8192 | E37: fp8 | F37: fp16 | G37: fp32 | H37: 524288 | I37: 0 | J37: 0 | K37: 0 | L37: 64 | M37: 0 | N37: 70368744177664 | O37: 70394513981440 | P37: 54878.05 | Q37: 1282.27 | R37: 0 | S37: 0 | T37: 0 | U37: 0
A38: =B38&"-"&C38&"-"&D38&"-"&E38&"-"&F38&"-"&G38 -> 16384-1-16384-int8-int32-int32 | B38: 16384 | C38: 1 | D38: 16384 | E38: int8 | F38: int32 | G38: int32 | H38: 131072 | I38: 0 | J38: 0 | K38: 0 | L38: 64 | M38: 0 | N38: 70368744177664 | O38: 70390219014144 | P38: 45047.63 | Q38: 1562.1 | R38: 0 | S38: 0 | T38: 0 | U38: 0
A39: =B39&"-"&C39&"-"&D39&"-"&E39&"-"&F39&"-"&G39 -> 32768-1-32768-bf16-bf16-fp32 | B39: 32768 | C39: 1 | D39: 32768 | E39: bf16 | F39: bf16 | G39: fp32 | H39: 65536 | I39: 0 | J39: 0 | K39: 0 | L39: 64 | M39: 0 | N39: 140737488355328 | O39: 281492156579840 | P39: 32395.11 | Q39: 4344.41 | R39: 0 | S39: 0 | T39: 0 | U39: 0
A40: =B40&"-"&C40&"-"&D40&"-"&E40&"-"&F40&"-"&G40 -> 16384-1-16384-bf16-bf16-fp32 | B40: 16384 | C40: 1 | D40: 16384 | E40: bf16 | F40: bf16 | G40: fp32 | H40: 131072 | I40: 0 | J40: 0 | K40: 0 | L40: 64 | M40: 0 | N40: 70368744177664 | O40: 140754668224512 | P40: 21477.96 | Q40: 3276.32 | R40: 0 | S40: 0 | T40: 0 | U40: 0
A41: =B41&"-"&C41&"-"&D41&"-"&E41&"-"&F41&"-"&G41 -> 16384-1-16384-fp8-fp8-fp32 | B41: 16384 | C41: 1 | D41: 16384 | E41: fp8 | F41: fp8 | G41: fp32 | H41: 131072 | I41: 0 | J41: 0 | K41: 0 | L41: 64 | M41: 0 | N41: 70368744177664 | O41: 70377334112256 | P41: 54900.69 | Q41: 1281.75 | R41: 0 | S41: 0 | T41: 0 | U41: 0
A42: =B42&"-"&C42&"-"&D42&"-"&E42&"-"&F42&"-"&G42 -> 98304-1-98304-fp32-fp32-fp32 | B42: 98304 | C42: 1 | D42: 98304 | E42: fp32 | F42: fp32 | G42: fp32 | H42: 32768 | I42: 0 | J42: 0 | K42: 0 | L42: 64 | M42: 0 | N42: 633318697598976 | O42: 2.5333263e+15 | P42: 319136.12 | Q42: 1984.48 | R42: 0 | S42: 0 | T42: 0 | U42: 0
A43: =B43&"-"&C43&"-"&D43&"-"&E43&"-"&F43&"-"&G43 -> 8192-1-8192-fp16-fp16-fp16 | B43: 8192 | C43: 1 | D43: 8192 | E43: fp16 | F43: fp16 | G43: fp16
A44: =B44&"-"&C44&"-"&D44&"-"&E44&"-"&F44&"-"&G44 -> 8192-1-8192-bf16-fp32-fp32 | B44: 8192 | C44: 1 | D44: 8192 | E44: bf16 | F44: fp32 | G44: fp32 | H44: 524288 | I44: 0 | J44: 0 | K44: 0 | L44: 64 | M44: 0 | N44: 70368744177664 | O44: 140789027962880 | P44: 30861.12 | Q44: 2280.18 | R44: 0 | S44: 0 | T44: 0 | U44: 0
A45: =B45&"-"&C45&"-"&D45&"-"&E45&"-"&F45&"-"&G45 -> 98304-1-98304-fp8-fp8-fp32 | B45: 98304 | C45: 1 | D45: 98304 | E45: fp8 | F45: fp8 | G45: fp32 | H45: 32768 | I45: 0 | J45: 0 | K45: 0 | L45: 64 | M45: 0 | N45: 633318697598976 | O45: 633331582500864 | P45: 507056.31 | Q45: 1249.01 | R45: 0 | S45: 0 | T45: 0 | U45: 0
A46: =B46&"-"&C46&"-"&D46&"-"&E46&"-"&F46&"-"&G46 -> 4096-1-4096-bf8-bf8-fp32 | B46: 4096 | C46: 1 | D46: 4096 | E46: bf8 | F46: bf8 | G46: fp32 | H46: 524288 | I46: 0 | J46: 0 | K46: 0 | L46: 64 | M46: 0 | N46: 17592186044416 | O46: 17600775979008 | P46: 31612.61 | Q46: 556.49 | R46: 0 | S46: 0 | T46: 0 | U46: 0
A47: =B47&"-"&C47&"-"&D47&"-"&E47&"-"&F47&"-"&G47 -> 65536-1-65536-bf8-fp16-fp32 | B47: 65536 | C47: 1 | D47: 65536 | E47: bf8 | F47: fp16 | G47: fp32 | H47: 32768 | I47: 0 | J47: 0 | K47: 0 | L47: 64 | M47: 0 | N47: 281474976710656 | O47: 281487861612544 | P47: 198802.78 | Q47: 1415.85 | R47: 0 | S47: 0 | T47: 0 | U47: 0
A48: =B48&"-"&C48&"-"&D48&"-"&E48&"-"&F48&"-"&G48 -> 16384-1-16384-fp8-fp32-fp32 | B48: 16384 | C48: 1 | D48: 16384 | E48: fp8 | F48: fp32 | G48: fp32 | H48: 131072 | I48: 0 | J48: 0 | K48: 0 | L48: 64 | M48: 0 | N48: 70368744177664 | O48: 70390219014144 | P48: 54792.55 | Q48: 1284.28 | R48: 0 | S48: 0 | T48: 0 | U48: 0
A49: =B49&"-"&C49&"-"&D49&"-"&E49&"-"&F49&"-"&G49 -> 65536-1-65536-fp8-fp8-fp32 | B49: 65536 | C49: 1 | D49: 65536 | E49: fp8 | F49: fp8 | G49: fp32 | H49: 32768 | I49: 0 | J49: 0 | K49: 0 | L49: 64 | M49: 0 | N49: 281474976710656 | O49: 281483566645248 | P49: 198803.23 | Q49: 1415.85 | R49: 0 | S49: 0 | T49: 0 | U49: 0
A50: =B50&"-"&C50&"-"&D50&"-"&E50&"-"&F50&"-"&G50 -> 32768-1-32768-fp32-fp32-fp32 | B50: 32768 | C50: 1 | D50: 32768 | E50: fp32 | F50: fp32 | G50: fp32 | H50: 65536 | I50: 0 | J50: 0 | K50: 0 | L50: 64 | M50: 0 | N50: 140737488355328 | O50: 562984313159680 | P50: 85121.05 | Q50: 1653.38 | R50: 0 | S50: 0 | T50: 0 | U50: 0
A51: =B51&"-"&C51&"-"&D51&"-"&E51&"-"&F51&"-"&G51 -> 4096-1-4096-bf8-fp32-fp32 | B51: 4096 | C51: 1 | D51: 4096 | E51: bf8 | F51: fp32 | G51: fp32 | H51: 524288 | I51: 0 | J51: 0 | K51: 0 | L51: 64 | M51: 0 | N51: 17592186044416 | O51: 17613660880896 | P51: 22250.47 | Q51: 790.64 | R51: 0 | S51: 0 | T51: 0 | U51: 0
A52: =B52&"-"&C52&"-"&D52&"-"&E52&"-"&F52&"-"&G52 -> 98304-1-98304-bf8-fp32-fp32 | B52: 98304 | C52: 1 | D52: 98304 | E52: bf8 | F52: fp32 | G52: fp32 | H52: 32768 | I52: 0 | J52: 0 | K52: 0 | L52: 64 | M52: 0 | N52: 633318697598976 | O52: 633350909853696 | P52: 506663.97 | Q52: 1249.98 | R52: 0 | S52: 0 | T52: 0 | U52: 0
...

Sheet hipblaslt_mi325x_750W_Auto_GF
B1: M | C1: N | D1: K | E1: mul | F1: acc | G1: scale | H1: n_iter | I1: n_thread | J1: n_wg | K1: n_wf | L1: wf_size | M1: wg_size | N1: n_flops | O1: n_bytes | P1: time_ms | Q1: gflop/s | R1: avg_clock | S1: max_clock | T1: min_clock | U1: stdev_clock
A2: =B2&"-"&C2&"-"&D2&"-"&E2&"-"&F2&"-"&G2 -> 4096-1-4096-fp16-fp32-fp32 | B2: 4096 | C2: 1 | D2: 4096 | E2: fp16 | F2: fp32 | G2: fp32 | H2: 524288 | I2: 0 | J2: 0 | K2: 0 | L2: 64 | M2: 0 | N2: 17592186044416 | O2: 35210141892608 | P2: 17104.72 | Q2: 1028.5 | R2: 0 | S2: 0 | T2: 0 | U2: 0
A3: =B3&"-"&C3&"-"&D3&"-"&E3&"-"&F3&"-"&G3 -> 4096-1-4096-bf8-fp16-fp32 | B3: 4096 | C3: 1 | D3: 4096 | E3: bf8 | F3: fp16 | G3: fp32 | H3: 524288 | I3: 0 | J3: 0 | K3: 0 | L3: 64 | M3: 0 | N3: 17592186044416 | O3: 17605070946304 | P3: 21685.33 | Q3: 811.25 | R3: 0 | S3: 0 | T3: 0 | U3: 0
A4: =B4&"-"&C4&"-"&D4&"-"&E4&"-"&F4&"-"&G4 -> 8192-1-8192-fp32-fp32-fp32 | B4: 8192 | C4: 1 | D4: 8192 | E4: fp32 | F4: fp32 | G4: fp32 | H4: 524288 | I4: 0 | J4: 0 | K4: 0 | L4: 64 | M4: 0 | N4: 70368744177664 | O4: 281543696187392 | P4: 74004.93 | Q4: 950.87 | R4: 0 | S4: 0 | T4: 0 | U4: 0
A5: =B5&"-"&C5&"-"&D5&"-"&E5&"-"&F5&"-"&G5 -> 8192-1-8192-fp16-fp16-fp32 | B5: 8192 | C5: 1 | D5: 8192 | E5: fp16 | F5: fp16 | G5: fp32 | H5: 524288 | I5: 0 | J5: 0 | K5: 0 | L5: 64 | M5: 0 | N5: 70368744177664 | O5: 140771848093696 | P5: 30704.18 | Q5: 2291.83 | R5: 0 | S5: 0 | T5: 0 | U5: 0
A6: =B6&"-"&C6&"-"&D6&"-"&E6&"-"&F6&"-"&G6 -> 8192-1-8192-fp8-fp32-fp32 | B6: 8192 | C6: 1 | D6: 8192 | E6: fp8 | F6: fp32 | G6: fp32 | H6: 524288 | I6: 0 | J6: 0 | K6: 0 | L6: 64 | M6: 0 | N6: 70368744177664 | O6: 70411693850624 | P6: 54019.93 | Q6: 1302.64 | R6: 0 | S6: 0 | T6: 0 | U6: 0
A7: =B7&"-"&C7&"-"&D7&"-"&E7&"-"&F7&"-"&G7 -> 65536-1-65536-tf32-fp32-fp32 | B7: 65536 | C7: 1 | D7: 65536 | E7: tf32 | F7: fp32 | G7: fp32 | H7: 32768 | I7: 0 | J7: 0 | K7: 0 | L7: 64 | M7: 0 | N7: 281474976710656 | O7: 1.1259343e+15 | P7: 298759.03 | Q7: 942.15 | R7: 0 | S7: 0 | T7: 0 | U7: 0
A8: =B8&"-"&C8&"-"&D8&"-"&E8&"-"&F8&"-"&G8 -> 4096-1-4096-fp64-fp64-fp64 | B8: 4096 | C8: 1 | D8: 4096 | E8: fp64 | F8: fp64 | G8: fp64 | H8: 524288 | I8: 0 | J8: 0 | K8: 0 | L8: 64 | M8: 0 | N8: 17592186044416 | O8: 140806207832064 | P8: 8970.68 | Q8: 1961.08 | R8: 0 | S8: 0 | T8: 0 | U8: 0
A9: =B9&"-"&C9&"-"&D9&"-"&E9&"-"&F9&"-"&G9 -> 16384-1-16384-fp64-fp64-fp64 | B9: 16384 | C9: 1 | D9: 16384 | E9: fp64 | F9: fp64 | G9: fp64 | H9: 131072 | I9: 0 | J9: 0 | K9: 0 | L9: 64 | M9: 0 | N9: 70368744177664 | O9: 563018672898048 | P9: 2343.29 | Q9: 30029.87 | R9: 0 | S9: 0 | T9: 0 | U9: 0
A10: =B10&"-"&C10&"-"&D10&"-"&E10&"-"&F10&"-"&G10 -> 32768-1-32768-bf16-fp32-fp32 | B10: 32768 | C10: 1 | D10: 32768 | E10: bf16 | F10: fp32 | G10: fp32 | H10: 65536 | I10: 0 | J10: 0 | K10: 0 | L10: 64 | M10: 0 | N10: 140737488355328 | O10: 281500746514432 | P10: 37291.93 | Q10: 3773.94 | R10: 0 | S10: 0 | T10: 0 | U10: 0
A11: =B11&"-"&C11&"-"&D11&"-"&E11&"-"&F11&"-"&G11 -> 8192-1-8192-fp16-fp32-fp32 | B11: 8192 | C11: 1 | D11: 8192 | E11: fp16 | F11: fp32 | G11: fp32 | H11: 524288 | I11: 0 | J11: 0 | K11: 0 | L11: 64 | M11: 0 | N11: 70368744177664 | O11: 140789027962880 | P11: 30435.78 | Q11: 2312.04 | R11: 0 | S11: 0 | T11: 0 | U11: 0
A12: =B12&"-"&C12&"-"&D12&"-"&E12&"-"&F12&"-"&G12 -> 98304-1-98304-int8-int32-int32 | B12: 98304 | C12: 1 | D12: 98304 | E12: int8 | F12: int32 | G12: int32 | H12: 32768 | I12: 0 | J12: 0 | K12: 0 | L12: 64 | M12: 0 | N12: 633318697598976 | O12: 633350909853696 | P12: 177734.62 | Q12: 3563.28 | R12: 0 | S12: 0 | T12: 0 | U12: 0
A13: =B13&"-"&C13&"-"&D13&"-"&E13&"-"&F13&"-"&G13 -> 16384-1-16384-fp32-fp32-fp32 | B13: 16384 | C13: 1 | D13: 16384 | E13: fp32 | F13: fp32 | G13: fp32 | H13: 131072 | I13: 0 | J13: 0 | K13: 0 | L13: 64 | M13: 0 | N13: 70368744177664 | O13: 281509336449024 | P13: 51459.82 | Q13: 1367.45 | R13: 0 | S13: 0 | T13: 0 | U13: 0
... A26: =B26&"-"&C26&"-"&D26&"-"&E26&"-"&F26&"-"&G26 -> 4096-1-4096-fp8-fp8-fp32 | B26: 4096 | C26: 1 | D26: 4096 | E26: fp8 | F26: fp8 | G26: fp32 | H26: 524288 | I26: 0 | J26: 0 | K26: 0 | L26: 64 | M26: 0 | N26: 17592186044416 | O26: 17600775979008 | P26: 21831.32 | Q26: 805.82 | R26: 0 | S26: 0 | T26: 0 | U26: 0
A27: =B27&"-"&C27&"-"&D27&"-"&E27&"-"&F27&"-"&G27 -> 65536-1-65536-fp16-fp16-fp16 | B27: 65536 | C27: 1 | D27: 65536 | E27: fp16 | F27: fp16 | G27: fp16
A28: =B28&"-"&C28&"-"&D28&"-"&E28&"-"&F28&"-"&G28 -> 16384-1-16384-bf8-fp32-fp32 | B28: 16384 | C28: 1 | D28: 16384 | E28: bf8 | F28: fp32 | G28: fp32 | H28: 131072 | I28: 0 | J28: 0 | K28: 0 | L28: 64 | M28: 0 | N28: 70368744177664 | O28: 70390219014144 | P28: 54614.11 | Q28: 1288.47 | R28: 0 | S28: 0 | T28: 0 | U28: 0
A29: =B29&"-"&C29&"-"&D29&"-"&E29&"-"&F29&"-"&G29 -> 8192-1-8192-tf32-fp32-fp32 | B29: 8192 | C29: 1 | D29: 8192 | E29: tf32 | F29: fp32 | G29: fp32 | H29: 524288 | I29: 0 | J29: 0 | K29: 0 | L29: 64 | M29: 0 | N29: 70368744177664 | O29: 281543696187392 | P29: 74029.46 | Q29: 950.55 | R29: 0 | S29: 0 | T29: 0 | U29: 0
A30: =B30&"-"&C30&"-"&D30&"-"&E30&"-"&F30&"-"&G30 -> 4096-1-4096-tf32-fp32-fp32 | B30: 4096 | C30: 1 | D30: 4096 | E30: tf32 | F30: fp32 | G30: fp32 | H30: 524288 | I30: 0 | J30: 0 | K30: 0 | L30: 64 | M30: 0 | N30: 17592186044416 | O30: 70403103916032 | P30: 37153.53 | Q30: 473.5 | R30: 0 | S30: 0 | T30: 0 | U30: 0
A31: =B31&"-"&C31&"-"&D31&"-"&E31&"-"&F31&"-"&G31 -> 4096-1-4096-fp16-fp16-fp16 | B31: 4096 | C31: 1 | D31: 4096 | E31: fp16 | F31: fp16 | G31: fp16
A32: =B32&"-"&C32&"-"&D32&"-"&E32&"-"&F32&"-"&G32 -> 16384-1-16384-fp16-fp16-fp16 | B32: 16384 | C32: 1 | D32: 16384 | E32: fp16 | F32: fp16 | G32: fp16
A33: =B33&"-"&C33&"-"&D33&"-"&E33&"-"&F33&"-"&G33 -> 8192-1-8192-fp8-fp8-fp32 | B33: 8192 | C33: 1 | D33: 8192 | E33: fp8 | F33: fp8 | G33: fp32 | H33: 524288 | I33: 0 | J33: 0 | K33: 0 | L33: 64 | M33: 0 | N33: 70368744177664 | O33: 70385924046848 | P33: 54227.81 | Q33: 1297.65 | R33: 0 | S33: 0 | T33: 0 | U33: 0
A34: =B34&"-"&C34&"-"&D34&"-"&E34&"-"&F34&"-"&G34 -> 65536-1-65536-fp16-fp32-fp32 | B34: 65536 | C34: 1 | D34: 65536 | E34: fp16 | F34: fp32 | G34: fp32 | H34: 32768 | I34: 0 | J34: 0 | K34: 0 | L34: 64 | M34: 0 | N34: 281474976710656 | O34: 562975723225088 | P34: 63600.12 | Q34: 4425.7 | R34: 0 | S34: 0 | T34: 0 | U34: 0
A35: =B35&"-"&C35&"-"&D35&"-"&E35&"-"&F35&"-"&G35 -> 98304-1-98304-bf8-bf8-fp32 | B35: 98304 | C35: 1 | D35: 98304 | E35: bf8 | F35: bf8 | G35: fp32 | H35: 32768 | I35: 0 | J35: 0 | K35: 0 | L35: 64 | M35: 0 | N35: 633318697598976 | O35: 633331582500864 | P35: 447207.25 | Q35: 1416.16 | R35: 0 | S35: 0 | T35: 0 | U35: 0
A36: =B36&"-"&C36&"-"&D36&"-"&E36&"-"&F36&"-"&G36 -> 16384-1-16384-bf16-fp32-fp32 | B36: 16384 | C36: 1 | D36: 16384 | E36: bf16 | F36: fp32 | G36: fp32 | H36: 131072 | I36: 0 | J36: 0 | K36: 0 | L36: 64 | M36: 0 | N36: 70368744177664 | O36: 140763258159104 | P36: 18764.86 | Q36: 3750.03 | R36: 0 | S36: 0 | T36: 0 | U36: 0
A37: =B37&"-"&C37&"-"&D37&"-"&E37&"-"&F37&"-"&G37 -> 8192-1-8192-fp8-fp16-fp32 | B37: 8192 | C37: 1 | D37: 8192 | E37: fp8 | F37: fp16 | G37: fp32 | H37: 524288 | I37: 0 | J37: 0 | K37: 0 | L37: 64 | M37: 0 | N37: 70368744177664 | O37: 70394513981440 | P37: 53897.86 | Q37: 1305.59 | R37: 0 | S37: 0 | T37: 0 | U37: 0
A38: =B38&"-"&C38&"-"&D38&"-"&E38&"-"&F38&"-"&G38 -> 16384-1-16384-int8-int32-int32 | B38: 16384 | C38: 1 | D38: 16384 | E38: int8 | F38: int32 | G38: int32 | H38: 131072 | I38: 0 | J38: 0 | K38: 0 | L38: 64 | M38: 0 | N38: 70368744177664 | O38: 70390219014144 | P38: 45299.13 | Q38: 1553.42 | R38: 0 | S38: 0 | T38: 0 | U38: 0
A39: =B39&"-"&C39&"-"&D39&"-"&E39&"-"&F39&"-"&G39 -> 32768-1-32768-bf16-bf16-fp32 | B39: 32768 | C39: 1 | D39: 32768 | E39: bf16 | F39: bf16 | G39: fp32 | H39: 65536 | I39: 0 | J39: 0 | K39: 0 | L39: 64 | M39: 0 | N39: 140737488355328 | O39: 281492156579840 | P39: 32047.4 | Q39: 4391.54 | R39: 0 | S39: 0 | T39: 0 | U39: 0
A40: =B40&"-"&C40&"-"&D40&"-"&E40&"-"&F40&"-"&G40 -> 16384-1-16384-bf16-bf16-fp32 | B40: 16384 | C40: 1 | D40: 16384 | E40: bf16 | F40: bf16 | G40: fp32 | H40: 131072 | I40: 0 | J40: 0 | K40: 0 | L40: 64 | M40: 0 | N40: 70368744177664 | O40: 140754668224512 | P40: 20634.04 | Q40: 3410.32 | R40: 0 | S40: 0 | T40: 0 | U40: 0
A41: =B41&"-"&C41&"-"&D41&"-"&E41&"-"&F41&"-"&G41 -> 16384-1-16384-fp8-fp8-fp32 | B41: 16384 | C41: 1 | D41: 16384 | E41: fp8 | F41: fp8 | G41: fp32 | H41: 131072 | I41: 0 | J41: 0 | K41: 0 | L41: 64 | M41: 0 | N41: 70368744177664 | O41: 70377334112256 | P41: 54518.18 | Q41: 1290.74 | R41: 0 | S41: 0 | T41: 0 | U41: 0
A42: =B42&"-"&C42&"-"&D42&"-"&E42&"-"&F42&"-"&G42 -> 98304-1-98304-fp32-fp32-fp32 | B42: 98304 | C42: 1 | D42: 98304 | E42: fp32 | F42: fp32 | G42: fp32 | H42: 32768 | I42: 0 | J42: 0 | K42: 0 | L42: 64 | M42: 0 | N42: 633318697598976 | O42: 2.5333263e+15 | P42: 307751.81 | Q42: 2057.89 | R42: 0 | S42: 0 | T42: 0 | U42: 0
A43: =B43&"-"&C43&"-"&D43&"-"&E43&"-"&F43&"-"&G43 -> 8192-1-8192-fp16-fp16-fp16 | B43: 8192 | C43: 1 | D43: 8192 | E43: fp16 | F43: fp16 | G43: fp16
A44: =B44&"-"&C44&"-"&D44&"-"&E44&"-"&F44&"-"&G44 -> 8192-1-8192-bf16-fp32-fp32 | B44: 8192 | C44: 1 | D44: 8192 | E44: bf16 | F44: fp32 | G44: fp32 | H44: 524288 | I44: 0 | J44: 0 | K44: 0 | L44: 64 | M44: 0 | N44: 70368744177664 | O44: 140789027962880 | P44: 30365.77 | Q44: 2317.37 | R44: 0 | S44: 0 | T44: 0 | U44: 0
A45: =B45&"-"&C45&"-"&D45&"-"&E45&"-"&F45&"-"&G45 -> 98304-1-98304-fp8-fp8-fp32 | B45: 98304 | C45: 1 | D45: 98304 | E45: fp8 | F45: fp8 | G45: fp32 | H45: 32768 | I45: 0 | J45: 0 | K45: 0 | L45: 64 | M45: 0 | N45: 633318697598976 | O45: 633331582500864 | P45: 512754.28 | Q45: 1235.13 | R45: 0 | S45: 0 | T45: 0 | U45: 0
A46: =B46&"-"&C46&"-"&D46&"-"&E46&"-"&F46&"-"&G46 -> 4096-1-4096-bf8-bf8-fp32 | B46: 4096 | C46: 1 | D46: 4096 | E46: bf8 | F46: bf8 | G46: fp32 | H46: 524288 | I46: 0 | J46: 0 | K46: 0 | L46: 64 | M46: 0 | N46: 17592186044416 | O46: 17600775979008 | P46: 31149.22 | Q46: 564.77 | R46: 0 | S46: 0 | T46: 0 | U46: 0
A47: =B47&"-"&C47&"-"&D47&"-"&E47&"-"&F47&"-"&G47 -> 65536-1-65536-bf8-fp16-fp32 | B47: 65536 | C47: 1 | D47: 65536 | E47: bf8 | F47: fp16 | G47: fp32 | H47: 32768 | I47: 0 | J47: 0 | K47: 0 | L47: 64 | M47: 0 | N47: 281474976710656 | O47: 281487861612544 | P47: 199338.59 | Q47: 1412.04 | R47: 0 | S47: 0 | T47: 0 | U47: 0
A48: =B48&"-"&C48&"-"&D48&"-"&E48&"-"&F48&"-"&G48 -> 16384-1-16384-fp8-fp32-fp32 | B48: 16384 | C48: 1 | D48: 16384 | E48: fp8 | F48: fp32 | G48: fp32 | H48: 131072 | I48: 0 | J48: 0 | K48: 0 | L48: 64 | M48: 0 | N48: 70368744177664 | O48: 70390219014144 | P48: 54751.93 | Q48: 1285.23 | R48: 0 | S48: 0 | T48: 0 | U48: 0
A49: =B49&"-"&C49&"-"&D49&"-"&E49&"-"&F49&"-"&G49 -> 65536-1-65536-fp8-fp8-fp32 | B49: 65536 | C49: 1 | D49: 65536 | E49: fp8 | F49: fp8 | G49: fp32 | H49: 32768 | I49: 0 | J49: 0 | K49: 0 | L49: 64 | M49: 0 | N49: 281474976710656 | O49: 281483566645248 | P49: 199322.2 | Q49: 1412.16 | R49: 0 | S49: 0 | T49: 0 | U49: 0
A50: =B50&"-"&C50&"-"&D50&"-"&E50&"-"&F50&"-"&G50 -> 32768-1-32768-fp32-fp32-fp32 | B50: 32768 | C50: 1 | D50: 32768 | E50: fp32 | F50: fp32 | G50: fp32 | H50: 65536 | I50: 0 | J50: 0 | K50: 0 | L50: 64 | M50: 0 | N50: 140737488355328 | O50: 562984313159680 | P50: 86899.88 | Q50: 1619.54 | R50: 0 | S50: 0 | T50: 0 | U50: 0
A51: =B51&"-"&C51&"-"&D51&"-"&E51&"-"&F51&"-"&G51 -> 4096-1-4096-bf8-fp32-fp32 | B51: 4096 | C51: 1 | D51: 4096 | E51: bf8 | F51: fp32 | G51: fp32 | H51: 524288 | I51: 0 | J51: 0 | K51: 0 | L51: 64 | M51: 0 | N51: 17592186044416 | O51: 17613660880896 | P51: 21714.45 | Q51: 810.16 | R51: 0 | S51: 0 | T51: 0 | U51: 0
A52: =B52&"-"&C52&"-"&D52&"-"&E52&"-"&F52&"-"&G52 -> 98304-1-98304-bf8-fp32-fp32 | B52: 98304 | C52: 1 | D52: 98304 | E52: bf8 | F52: fp32 | G52: fp32 | H52: 32768 | I52: 0 | J52: 0 | K52: 0 | L52: 64 | M52: 0 | N52: 633318697598976 | O52: 633350909853696 | P52: 512869.16 | Q52: 1234.85 | R52: 0 | S52: 0 | T52: 0 | U52: 0
...

Sheet hipblaslt_mi325x_750W_Manual_GF
B1: M | C1: N | D1: K | E1: mul | F1: acc | G1: scale | H1: n_iter | I1: n_thread | J1: n_wg | K1: n_wf | L1: wf_size | M1: wg_size | N1: n_flops | O1: n_bytes | P1: time_ms | Q1: gflop/s | R1: avg_clock | S1: max_clock | T1: min_clock | U1: stdev_clock
A2: =B2&"-"&C2&"-"&D2&"-"&E2&"-"&F2&"-"&G2 -> 4096-1-4096-fp16-fp32-fp32 | B2: 4096 | C2: 1 | D2: 4096 | E2: fp16 | F2: fp32 | G2: fp32 | H2: 524288 | I2: 0 | J2: 0 | K2: 0 | L2: 64 | M2: 0 | N2: 17592186044416 | O2: 35210141892608 | P2: 20515.09 | Q2: 857.52 | R2: 0 | S2: 0 | T2: 0 | U2: 0
A3: =B3&"-"&C3&"-"&D3&"-"&E3&"-"&F3&"-"&G3 -> 4096-1-4096-bf8-fp16-fp32 | B3: 4096 | C3: 1 | D3: 4096 | E3: bf8 | F3: fp16 | G3: fp32 | H3: 524288 | I3: 0 | J3: 0 | K3: 0 | L3: 64 | M3: 0 | N3: 17592186044416 | O3: 17605070946304 | P3: 25467.42 | Q3: 690.77 | R3: 0 | S3: 0 | T3: 0 | U3: 0
A4: =B4&"-"&C4&"-"&D4&"-"&E4&"-"&F4&"-"&G4 -> 8192-1-8192-fp32-fp32-fp32 | B4: 8192 | C4: 1 | D4: 8192 | E4: fp32 | F4: fp32 | G4: fp32 | H4: 524288 | I4: 0 | J4: 0 | K4: 0 | L4: 64 | M4: 0 | N4: 70368744177664 | O4: 281543696187392 | P4: 106861.75 | Q4: 658.5 | R4: 0 | S4: 0 | T4: 0 | U4: 0
A5: =B5&"-"&C5&"-"&D5&"-"&E5&"-"&F5&"-"&G5 -> 8192-1-8192-fp16-fp16-fp32 | B5: 8192 | C5: 1 | D5: 8192 | E5: fp16 | F5: fp16 | G5: fp32 | H5: 524288 | I5: 0 | J5: 0 | K5: 0 | L5: 64 | M5: 0 | N5: 70368744177664 | O5: 140771848093696 | P5: 38164.29 | Q5: 1843.84 | R5: 0 | S5: 0 | T5: 0 | U5: 0
A6: =B6&"-"&C6&"-"&D6&"-"&E6&"-"&F6&"-"&G6 -> 8192-1-8192-fp8-fp32-fp32 | B6: 8192 | C6: 1 | D6: 8192 | E6: fp8 | F6: fp32 | G6: fp32 | H6: 524288 | I6: 0 | J6: 0 | K6: 0 | L6: 64 | M6: 0 | N6: 70368744177664 | O6: 70411693850624 | P6: 55580.52 | Q6: 1266.07 | R6: 0 | S6: 0 | T6: 0 | U6: 0
A7: =B7&"-"&C7&"-"&D7&"-"&E7&"-"&F7&"-"&G7 -> 65536-1-65536-tf32-fp32-fp32 | B7: 65536 | C7: 1 | D7: 65536 | E7: tf32 | F7: fp32 | G7: fp32 | H7: 32768 | I7: 0 | J7: 0 | K7: 0 | L7: 64 | M7: 0 | N7: 281474976710656 | O7: 1.1259343e+15 | P7: 333835 | Q7: 843.16 | R7: 0 | S7: 0 | T7: 0 | U7: 0
A8: =B8&"-"&C8&"-"&D8&"-"&E8&"-"&F8&"-"&G8 -> 4096-1-4096-fp64-fp64-fp64 | B8: 4096 | C8: 1 | D8: 4096 | E8: fp64 | F8: fp64 | G8: fp64 | H8: 524288 | I8: 0 | J8: 0 | K8: 0 | L8: 64 | M8: 0 | N8: 17592186044416 | O8: 140806207832064 | P8: 9957.8 | Q8: 1766.67 | R8: 0 | S8: 0 | T8: 0 | U8: 0
A9: =B9&"-"&C9&"-"&D9&"-"&E9&"-"&F9&"-"&G9 -> 16384-1-16384-fp64-fp64-fp64 | B9: 16384 | C9: 1 | D9: 16384 | E9: fp64 | F9: fp64 | G9: fp64 | H9: 131072 | I9: 0 | J9: 0 | K9: 0 | L9: 64 | M9: 0 | N9: 70368744177664 | O9: 563018672898048 | P9: 2664.35 | Q9: 26411.25 | R9: 0 | S9: 0 | T9: 0 | U9: 0
A10: =B10&"-"&C10&"-"&D10&"-"&E10&"-"&F10&"-"&G10 -> 32768-1-32768-bf16-fp32-fp32 | B10: 32768 | C10: 1 | D10: 32768 | E10: bf16 | F10: fp32 | G10: fp32 | H10: 65536 | I10: 0 | J10: 0 | K10: 0 | L10: 64 | M10: 0 | N10: 140737488355328 | O10: 281500746514432 | P10: 42821.66 | Q10: 3286.6 | R10: 0 | S10: 0 | T10: 0 | U10: 0
A11: =B11&"-"&C11&"-"&D11&"-"&E11&"-"&F11&"-"&G11 -> 8192-1-8192-fp16-fp32-fp32 | B11: 8192 | C11: 1 | D11: 8192 | E11: fp16 | F11: fp32 | G11: fp32 | H11: 524288 | I11: 0 | J11: 0 | K11: 0 | L11: 64 | M11: 0 | N11: 70368744177664 | O11: 140789027962880 | P11: 38001.04 | Q11: 1851.76 | R11: 0 | S11: 0 | T11: 0 | U11: 0
A12: =B12&"-"&C12&"-"&D12&"-"&E12&"-"&F12&"-"&G12 -> 98304-1-98304-int8-int32-int32 | B12: 98304 | C12: 1 | D12: 98304 | E12: int8 | F12: int32 | G12: int32 | H12: 32768 | I12: 0 | J12: 0 | K12: 0 | L12: 64 | M12: 0 | N12: 633318697598976 | O12: 633350909853696 | P12: 217520.2 | Q12: 2911.54 | R12: 0 | S12: 0 | T12: 0 | U12: 0
A13: =B13&"-"&C13&"-"&D13&"-"&E13&"-"&F13&"-"&G13 -> 16384-1-16384-fp32-fp32-fp32 | B13: 16384 | C13: 1 | D13: 16384 | E13: fp32 | F13: fp32 | G13: fp32 | H13: 131072 | I13: 0 | J13: 0 | K13: 0 | L13: 64 | M13: 0 | N13: 70368744177664 | O13: 281509336449024 | P13: 75282.79 | Q13: 934.73 | R13: 0 | S13: 0 | T13: 0 | U13: 0
... A26: =B26&"-"&C26&"-"&D26&"-"&E26&"-"&F26&"-"&G26 -> 4096-1-4096-fp8-fp8-fp32 | B26: 4096 | C26: 1 | D26: 4096 | E26: fp8 | F26: fp8 | G26: fp32 | H26: 524288 | I26: 0 | J26: 0 | K26: 0 | L26: 64 | M26: 0 | N26: 17592186044416 | O26: 17600775979008 | P26: 25636.3 | Q26: 686.22 | R26: 0 | S26: 0 | T26: 0 | U26: 0
A27: =B27&"-"&C27&"-"&D27&"-"&E27&"-"&F27&"-"&G27 -> 65536-1-65536-fp16-fp16-fp16 | B27: 65536 | C27: 1 | D27: 65536 | E27: fp16 | F27: fp16 | G27: fp16
A28: =B28&"-"&C28&"-"&D28&"-"&E28&"-"&F28&"-"&G28 -> 16384-1-16384-bf8-fp32-fp32 | B28: 16384 | C28: 1 | D28: 16384 | E28: bf8 | F28: fp32 | G28: fp32 | H28: 131072 | I28: 0 | J28: 0 | K28: 0 | L28: 64 | M28: 0 | N28: 70368744177664 | O28: 70390219014144 | P28: 55567.04 | Q28: 1266.38 | R28: 0 | S28: 0 | T28: 0 | U28: 0
A29: =B29&"-"&C29&"-"&D29&"-"&E29&"-"&F29&"-"&G29 -> 8192-1-8192-tf32-fp32-fp32 | B29: 8192 | C29: 1 | D29: 8192 | E29: tf32 | F29: fp32 | G29: fp32 | H29: 524288 | I29: 0 | J29: 0 | K29: 0 | L29: 64 | M29: 0 | N29: 70368744177664 | O29: 281543696187392 | P29: 99146 | Q29: 709.75 | R29: 0 | S29: 0 | T29: 0 | U29: 0
A30: =B30&"-"&C30&"-"&D30&"-"&E30&"-"&F30&"-"&G30 -> 4096-1-4096-tf32-fp32-fp32 | B30: 4096 | C30: 1 | D30: 4096 | E30: tf32 | F30: fp32 | G30: fp32 | H30: 524288 | I30: 0 | J30: 0 | K30: 0 | L30: 64 | M30: 0 | N30: 17592186044416 | O30: 70403103916032 | P30: 48773.15 | Q30: 360.69 | R30: 0 | S30: 0 | T30: 0 | U30: 0
A31: =B31&"-"&C31&"-"&D31&"-"&E31&"-"&F31&"-"&G31 -> 4096-1-4096-fp16-fp16-fp16 | B31: 4096 | C31: 1 | D31: 4096 | E31: fp16 | F31: fp16 | G31: fp16
A32: =B32&"-"&C32&"-"&D32&"-"&E32&"-"&F32&"-"&G32 -> 16384-1-16384-fp16-fp16-fp16 | B32: 16384 | C32: 1 | D32: 16384 | E32: fp16 | F32: fp16 | G32: fp16
A33: =B33&"-"&C33&"-"&D33&"-"&E33&"-"&F33&"-"&G33 -> 8192-1-8192-fp8-fp8-fp32 | B33: 8192 | C33: 1 | D33: 8192 | E33: fp8 | F33: fp8 | G33: fp32 | H33: 524288 | I33: 0 | J33: 0 | K33: 0 | L33: 64 | M33: 0 | N33: 70368744177664 | O33: 70385924046848 | P33: 55637.04 | Q33: 1264.78 | R33: 0 | S33: 0 | T33: 0 | U33: 0
A34: =B34&"-"&C34&"-"&D34&"-"&E34&"-"&F34&"-"&G34 -> 65536-1-65536-fp16-fp32-fp32 | B34: 65536 | C34: 1 | D34: 65536 | E34: fp16 | F34: fp32 | G34: fp32 | H34: 32768 | I34: 0 | J34: 0 | K34: 0 | L34: 64 | M34: 0 | N34: 281474976710656 | O34: 562975723225088 | P34: 62036.95 | Q34: 4537.22 | R34: 0 | S34: 0 | T34: 0 | U34: 0
A35: =B35&"-"&C35&"-"&D35&"-"&E35&"-"&F35&"-"&G35 -> 98304-1-98304-bf8-bf8-fp32 | B35: 98304 | C35: 1 | D35: 98304 | E35: bf8 | F35: bf8 | G35: fp32 | H35: 32768 | I35: 0 | J35: 0 | K35: 0 | L35: 64 | M35: 0 | N35: 633318697598976 | O35: 633331582500864 | P35: 457740.56 | Q35: 1383.58 | R35: 0 | S35: 0 | T35: 0 | U35: 0
A36: =B36&"-"&C36&"-"&D36&"-"&E36&"-"&F36&"-"&G36 -> 16384-1-16384-bf16-fp32-fp32 | B36: 16384 | C36: 1 | D36: 16384 | E36: bf16 | F36: fp32 | G36: fp32 | H36: 131072 | I36: 0 | J36: 0 | K36: 0 | L36: 64 | M36: 0 | N36: 70368744177664 | O36: 140763258159104 | P36: 22112.72 | Q36: 3182.27 | R36: 0 | S36: 0 | T36: 0 | U36: 0
A37: =B37&"-"&C37&"-"&D37&"-"&E37&"-"&F37&"-"&G37 -> 8192-1-8192-fp8-fp16-fp32 | B37: 8192 | C37: 1 | D37: 8192 | E37: fp8 | F37: fp16 | G37: fp32 | H37: 524288 | I37: 0 | J37: 0 | K37: 0 | L37: 64 | M37: 0 | N37: 70368744177664 | O37: 70394513981440 | P37: 55553.43 | Q37: 1266.69 | R37: 0 | S37: 0 | T37: 0 | U37: 0
A38: =B38&"-"&C38&"-"&D38&"-"&E38&"-"&F38&"-"&G38 -> 16384-1-16384-int8-int32-int32 | B38: 16384 | C38: 1 | D38: 16384 | E38: int8 | F38: int32 | G38: int32 | H38: 131072 | I38: 0 | J38: 0 | K38: 0 | L38: 64 | M38: 0 | N38: 70368744177664 | O38: 70390219014144 | P38: 67236.25 | Q38: 1046.59 | R38: 0 | S38: 0 | T38: 0 | U38: 0
A39: =B39&"-"&C39&"-"&D39&"-"&E39&"-"&F39&"-"&G39 -> 32768-1-32768-bf16-bf16-fp32 | B39: 32768 | C39: 1 | D39: 32768 | E39: bf16 | F39: bf16 | G39: fp32 | H39: 65536 | I39: 0 | J39: 0 | K39: 0 | L39: 64 | M39: 0 | N39: 140737488355328 | O39: 281492156579840 | P39: 30203.19 | Q39: 4659.69 | R39: 0 | S39: 0 | T39: 0 | U39: 0
A40: =B40&"-"&C40&"-"&D40&"-"&E40&"-"&F40&"-"&G40 -> 16384-1-16384-bf16-bf16-fp32 | B40: 16384 | C40: 1 | D40: 16384 | E40: bf16 | F40: bf16 | G40: fp32 | H40: 131072 | I40: 0 | J40: 0 | K40: 0 | L40: 64 | M40: 0 | N40: 70368744177664 | O40: 140754668224512 | P40: 21453.54 | Q40: 3280.05 | R40: 0 | S40: 0 | T40: 0 | U40: 0
A41: =B41&"-"&C41&"-"&D41&"-"&E41&"-"&F41&"-"&G41 -> 16384-1-16384-fp8-fp8-fp32 | B41: 16384 | C41: 1 | D41: 16384 | E41: fp8 | F41: fp8 | G41: fp32 | H41: 131072 | I41: 0 | J41: 0 | K41: 0 | L41: 64 | M41: 0 | N41: 70368744177664 | O41: 70377334112256 | P41: 55556.44 | Q41: 1266.62 | R41: 0 | S41: 0 | T41: 0 | U41: 0
A42: =B42&"-"&C42&"-"&D42&"-"&E42&"-"&F42&"-"&G42 -> 98304-1-98304-fp32-fp32-fp32 | B42: 98304 | C42: 1 | D42: 98304 | E42: fp32 | F42: fp32 | G42: fp32 | H42: 32768 | I42: 0 | J42: 0 | K42: 0 | L42: 64 | M42: 0 | N42: 633318697598976 | O42: 2.5333263e+15 | P42: 302540.56 | Q42: 2093.33 | R42: 0 | S42: 0 | T42: 0 | U42: 0
A43: =B43&"-"&C43&"-"&D43&"-"&E43&"-"&F43&"-"&G43 -> 8192-1-8192-fp16-fp16-fp16 | B43: 8192 | C43: 1 | D43: 8192 | E43: fp16 | F43: fp16 | G43: fp16
A44: =B44&"-"&C44&"-"&D44&"-"&E44&"-"&F44&"-"&G44 -> 8192-1-8192-bf16-fp32-fp32 | B44: 8192 | C44: 1 | D44: 8192 | E44: bf16 | F44: fp32 | G44: fp32 | H44: 524288 | I44: 0 | J44: 0 | K44: 0 | L44: 64 | M44: 0 | N44: 70368744177664 | O44: 140789027962880 | P44: 37869.54 | Q44: 1858.19 | R44: 0 | S44: 0 | T44: 0 | U44: 0
A45: =B45&"-"&C45&"-"&D45&"-"&E45&"-"&F45&"-"&G45 -> 98304-1-98304-fp8-fp8-fp32 | B45: 98304 | C45: 1 | D45: 98304 | E45: fp8 | F45: fp8 | G45: fp32 | H45: 32768 | I45: 0 | J45: 0 | K45: 0 | L45: 64 | M45: 0 | N45: 633318697598976 | O45: 633331582500864 | P45: 506880.09 | Q45: 1249.44 | R45: 0 | S45: 0 | T45: 0 | U45: 0
A46: =B46&"-"&C46&"-"&D46&"-"&E46&"-"&F46&"-"&G46 -> 4096-1-4096-bf8-bf8-fp32 | B46: 4096 | C46: 1 | D46: 4096 | E46: bf8 | F46: bf8 | G46: fp32 | H46: 524288 | I46: 0 | J46: 0 | K46: 0 | L46: 64 | M46: 0 | N46: 17592186044416 | O46: 17600775979008 | P46: 36841.24 | Q46: 477.51 | R46: 0 | S46: 0 | T46: 0 | U46: 0
A47: =B47&"-"&C47&"-"&D47&"-"&E47&"-"&F47&"-"&G47 -> 65536-1-65536-bf8-fp16-fp32 | B47: 65536 | C47: 1 | D47: 65536 | E47: bf8 | F47: fp16 | G47: fp32 | H47: 32768 | I47: 0 | J47: 0 | K47: 0 | L47: 64 | M47: 0 | N47: 281474976710656 | O47: 281487861612544 | P47: 197655.16 | Q47: 1424.07 | R47: 0 | S47: 0 | T47: 0 | U47: 0
A48: =B48&"-"&C48&"-"&D48&"-"&E48&"-"&F48&"-"&G48 -> 16384-1-16384-fp8-fp32-fp32 | B48: 16384 | C48: 1 | D48: 16384 | E48: fp8 | F48: fp32 | G48: fp32 | H48: 131072 | I48: 0 | J48: 0 | K48: 0 | L48: 64 | M48: 0 | N48: 70368744177664 | O48: 70390219014144 | P48: 55827.51 | Q48: 1260.47 | R48: 0 | S48: 0 | T48: 0 | U48: 0
A49: =B49&"-"&C49&"-"&D49&"-"&E49&"-"&F49&"-"&G49 -> 65536-1-65536-fp8-fp8-fp32 | B49: 65536 | C49: 1 | D49: 65536 | E49: fp8 | F49: fp8 | G49: fp32 | H49: 32768 | I49: 0 | J49: 0 | K49: 0 | L49: 64 | M49: 0 | N49: 281474976710656 | O49: 281483566645248 | P49: 197729.23 | Q49: 1423.54 | R49: 0 | S49: 0 | T49: 0 | U49: 0
A50: =B50&"-"&C50&"-"&D50&"-"&E50&"-"&F50&"-"&G50 -> 32768-1-32768-fp32-fp32-fp32 | B50: 32768 | C50: 1 | D50: 32768 | E50: fp32 | F50: fp32 | G50: fp32 | H50: 65536 | I50: 0 | J50: 0 | K50: 0 | L50: 64 | M50: 0 | N50: 140737488355328 | O50: 562984313159680 | P50: 101667.38 | Q50: 1384.29 | R50: 0 | S50: 0 | T50: 0 | U50: 0
A51: =B51&"-"&C51&"-"&D51&"-"&E51&"-"&F51&"-"&G51 -> 4096-1-4096-bf8-fp32-fp32 | B51: 4096 | C51: 1 | D51: 4096 | E51: bf8 | F51: fp32 | G51: fp32 | H51: 524288 | I51: 0 | J51: 0 | K51: 0 | L51: 64 | M51: 0 | N51: 17592186044416 | O51: 17613660880896 | P51: 25409.53 | Q51: 692.35 | R51: 0 | S51: 0 | T51: 0 | U51: 0
A52: =B52&"-"&C52&"-"&D52&"-"&E52&"-"&F52&"-"&G52 -> 98304-1-98304-bf8-fp32-fp32 | B52: 98304 | C52: 1 | D52: 98304 | E52: bf8 | F52: fp32 | G52: fp32 | H52: 32768 | I52: 0 | J52: 0 | K52: 0 | L52: 64 | M52: 0 | N52: 633318697598976 | O52: 633350909853696 | P52: 507751.88 | Q52: 1247.3 | R52: 0 | S52: 0 | T52: 0 | U52: 0
...

Sheet hipblaslt_mi325x_1000W_GF
B1: M | C1: N | D1: K | E1: mul | F1: acc | G1: scale | H1: n_iter | I1: n_thread | J1: n_wg | K1: n_wf | L1: wf_size | M1: wg_size | N1: n_flops | O1: n_bytes | P1: time_ms | Q1: gflop/s | R1: avg_clock | S1: max_clock | T1: min_clock | U1: stdev_clock
A2: =B2&"-"&C2&"-"&D2&"-"&E2&"-"&F2&"-"&G2 -> 4096-1-4096-fp16-fp32-fp32 | B2: 4096 | C2: 1 | D2: 4096 | E2: fp16 | F2: fp32 | G2: fp32 | H2: 524288 | I2: 0 | J2: 0 | K2: 0 | L2: 64 | M2: 0 | N2: 17592186044416 | O2: 35210141892608 | P2: 17150.64 | Q2: 1025.75 | R2: 0 | S2: 0 | T2: 0 | U2: 0
A3: =B3&"-"&C3&"-"&D3&"-"&E3&"-"&F3&"-"&G3 -> 4096-1-4096-bf8-fp16-fp32 | B3: 4096 | C3: 1 | D3: 4096 | E3: bf8 | F3: fp16 | G3: fp32 | H3: 524288 | I3: 0 | J3: 0 | K3: 0 | L3: 64 | M3: 0 | N3: 17592186044416 | O3: 17605070946304 | P3: 21612.75 | Q3: 813.97 | R3: 0 | S3: 0 | T3: 0 | U3: 0
A4: =B4&"-"&C4&"-"&D4&"-"&E4&"-"&F4&"-"&G4 -> 8192-1-8192-fp32-fp32-fp32 | B4: 8192 | C4: 1 | D4: 8192 | E4: fp32 | F4: fp32 | G4: fp32 | H4: 524288 | I4: 0 | J4: 0 | K4: 0 | L4: 64 | M4: 0 | N4: 70368744177664 | O4: 281543696187392 | P4: 74004.05 | Q4: 950.88 | R4: 0 | S4: 0 | T4: 0 | U4: 0
A5: =B5&"-"&C5&"-"&D5&"-"&E5&"-"&F5&"-"&G5 -> 8192-1-8192-fp16-fp16-fp32 | B5: 8192 | C5: 1 | D5: 8192 | E5: fp16 | F5: fp16 | G5: fp32 | H5: 524288 | I5: 0 | J5: 0 | K5: 0 | L5: 64 | M5: 0 | N5: 70368744177664 | O5: 140771848093696 | P5: 30711.17 | Q5: 2291.31 | R5: 0 | S5: 0 | T5: 0 | U5: 0
A6: =B6&"-"&C6&"-"&D6&"-"&E6&"-"&F6&"-"&G6 -> 8192-1-8192-fp8-fp32-fp32 | B6: 8192 | C6: 1 | D6: 8192 | E6: fp8 | F6: fp32 | G6: fp32 | H6: 524288 | I6: 0 | J6: 0 | K6: 0 | L6: 64 | M6: 0 | N6: 70368744177664 | O6: 70411693850624 | P6: 53905.32 | Q6: 1305.41 | R6: 0 | S6: 0 | T6: 0 | U6: 0
A7: =B7&"-"&C7&"-"&D7&"-"&E7&"-"&F7&"-"&G7 -> 65536-1-65536-tf32-fp32-fp32 | B7: 65536 | C7: 1 | D7: 65536 | E7: tf32 | F7: fp32 | G7: fp32 | H7: 32768 | I7: 0 | J7: 0 | K7: 0 | L7: 64 | M7: 0 | N7: 281474976710656 | O7: 1.1259343e+15 | P7: 261386.66 | Q7: 1076.85 | R7: 0 | S7: 0 | T7: 0 | U7: 0
A8: =B8&"-"&C8&"-"&D8&"-"&E8&"-"&F8&"-"&G8 -> 4096-1-4096-fp64-fp64-fp64 | B8: 4096 | C8: 1 | D8: 4096 | E8: fp64 | F8: fp64 | G8: fp64 | H8: 524288 | I8: 0 | J8: 0 | K8: 0 | L8: 64 | M8: 0 | N8: 17592186044416 | O8: 140806207832064 | P8: 9055.62 | Q8: 1942.68 | R8: 0 | S8: 0 | T8: 0 | U8: 0
A9: =B9&"-"&C9&"-"&D9&"-"&E9&"-"&F9&"-"&G9 -> 16384-1-16384-fp64-fp64-fp64 | B9: 16384 | C9: 1 | D9: 16384 | E9: fp64 | F9: fp64 | G9: fp64 | H9: 131072 | I9: 0 | J9: 0 | K9: 0 | L9: 64 | M9: 0 | N9: 70368744177664 | O9: 563018672898048 | P9: 2325.48 | Q9: 30259.92 | R9: 0 | S9: 0 | T9: 0 | U9: 0
A10: =B10&"-"&C10&"-"&D10&"-"&E10&"-"&F10&"-"&G10 -> 32768-1-32768-bf16-fp32-fp32 | B10: 32768 | C10: 1 | D10: 32768 | E10: bf16 | F10: fp32 | G10: fp32 | H10: 65536 | I10: 0 | J10: 0 | K10: 0 | L10: 64 | M10: 0 | N10: 140737488355328 | O10: 281500746514432 | P10: 35146.1 | Q10: 4004.36 | R10: 0 | S10: 0 | T10: 0 | U10: 0
A11: =B11&"-"&C11&"-"&D11&"-"&E11&"-"&F11&"-"&G11 -> 8192-1-8192-fp16-fp32-fp32 | B11: 8192 | C11: 1 | D11: 8192 | E11: fp16 | F11: fp32 | G11: fp32 | H11: 524288 | I11: 0 | J11: 0 | K11: 0 | L11: 64 | M11: 0 | N11: 70368744177664 | O11: 140789027962880 | P11: 30537.41 | Q11: 2304.35 | R11: 0 | S11: 0 | T11: 0 | U11: 0
A12: =B12&"-"&C12&"-"&D12&"-"&E12&"-"&F12&"-"&G12 -> 98304-1-98304-int8-int32-int32 | B12: 98304 | C12: 1 | D12: 98304 | E12: int8 | F12: int32 | G12: int32 | H12: 32768 | I12: 0 | J12: 0 | K12: 0 | L12: 64 | M12: 0 | N12: 633318697598976 | O12: 633350909853696 | P12: 156908.98 | Q12: 4036.22 | R12: 0 | S12: 0 | T12: 0 | U12: 0
A13: =B13&"-"&C13&"-"&D13&"-"&E13&"-"&F13&"-"&G13 -> 16384-1-16384-fp32-fp32-fp32 | B13: 16384 | C13: 1 | D13: 16384 | E13: fp32 | F13: fp32 | G13: fp32 | H13: 131072 | I13: 0 | J13: 0 | K13: 0 | L13: 64 | M13: 0 | N13: 70368744177664 | O13: 281509336449024 | P13: 51378.52 | Q13: 1369.61 | R13: 0 | S13: 0 | T13: 0 | U13: 0
... A26: =B26&"-"&C26&"-"&D26&"-"&E26&"-"&F26&"-"&G26 -> 4096-1-4096-fp8-fp8-fp32 | B26: 4096 | C26: 1 | D26: 4096 | E26: fp8 | F26: fp8 | G26: fp32 | H26: 524288 | I26: 0 | J26: 0 | K26: 0 | L26: 64 | M26: 0 | N26: 17592186044416 | O26: 17600775979008 | P26: 22063.53 | Q26: 797.34 | R26: 0 | S26: 0 | T26: 0 | U26: 0
A27: =B27&"-"&C27&"-"&D27&"-"&E27&"-"&F27&"-"&G27 -> 65536-1-65536-fp16-fp16-fp16 | B27: 65536 | C27: 1 | D27: 65536 | E27: fp16 | F27: fp16 | G27: fp16
A28: =B28&"-"&C28&"-"&D28&"-"&E28&"-"&F28&"-"&G28 -> 16384-1-16384-bf8-fp32-fp32 | B28: 16384 | C28: 1 | D28: 16384 | E28: bf8 | F28: fp32 | G28: fp32 | H28: 131072 | I28: 0 | J28: 0 | K28: 0 | L28: 64 | M28: 0 | N28: 70368744177664 | O28: 70390219014144 | P28: 54745 | Q28: 1285.39 | R28: 0 | S28: 0 | T28: 0 | U28: 0
A29: =B29&"-"&C29&"-"&D29&"-"&E29&"-"&F29&"-"&G29 -> 8192-1-8192-tf32-fp32-fp32 | B29: 8192 | C29: 1 | D29: 8192 | E29: tf32 | F29: fp32 | G29: fp32 | H29: 524288 | I29: 0 | J29: 0 | K29: 0 | L29: 64 | M29: 0 | N29: 70368744177664 | O29: 281543696187392 | P29: 74591.86 | Q29: 943.38 | R29: 0 | S29: 0 | T29: 0 | U29: 0
A30: =B30&"-"&C30&"-"&D30&"-"&E30&"-"&F30&"-"&G30 -> 4096-1-4096-tf32-fp32-fp32 | B30: 4096 | C30: 1 | D30: 4096 | E30: tf32 | F30: fp32 | G30: fp32 | H30: 524288 | I30: 0 | J30: 0 | K30: 0 | L30: 64 | M30: 0 | N30: 17592186044416 | O30: 70403103916032 | P30: 37154.17 | Q30: 473.49 | R30: 0 | S30: 0 | T30: 0 | U30: 0
A31: =B31&"-"&C31&"-"&D31&"-"&E31&"-"&F31&"-"&G31 -> 4096-1-4096-fp16-fp16-fp16 | B31: 4096 | C31: 1 | D31: 4096 | E31: fp16 | F31: fp16 | G31: fp16
A32: =B32&"-"&C32&"-"&D32&"-"&E32&"-"&F32&"-"&G32 -> 16384-1-16384-fp16-fp16-fp16 | B32: 16384 | C32: 1 | D32: 16384 | E32: fp16 | F32: fp16 | G32: fp16
A33: =B33&"-"&C33&"-"&D33&"-"&E33&"-"&F33&"-"&G33 -> 8192-1-8192-fp8-fp8-fp32 | B33: 8192 | C33: 1 | D33: 8192 | E33: fp8 | F33: fp8 | G33: fp32 | H33: 524288 | I33: 0 | J33: 0 | K33: 0 | L33: 64 | M33: 0 | N33: 70368744177664 | O33: 70385924046848 | P33: 54109.7 | Q33: 1300.48 | R33: 0 | S33: 0 | T33: 0 | U33: 0
A34: =B34&"-"&C34&"-"&D34&"-"&E34&"-"&F34&"-"&G34 -> 65536-1-65536-fp16-fp32-fp32 | B34: 65536 | C34: 1 | D34: 65536 | E34: fp16 | F34: fp32 | G34: fp32 | H34: 32768 | I34: 0 | J34: 0 | K34: 0 | L34: 64 | M34: 0 | N34: 281474976710656 | O34: 562975723225088 | P34: 59380.66 | Q34: 4740.18 | R34: 0 | S34: 0 | T34: 0 | U34: 0
A35: =B35&"-"&C35&"-"&D35&"-"&E35&"-"&F35&"-"&G35 -> 98304-1-98304-bf8-bf8-fp32 | B35: 98304 | C35: 1 | D35: 98304 | E35: bf8 | F35: bf8 | G35: fp32 | H35: 32768 | I35: 0 | J35: 0 | K35: 0 | L35: 64 | M35: 0 | N35: 633318697598976 | O35: 633331582500864 | P35: 446386.56 | Q35: 1418.77 | R35: 0 | S35: 0 | T35: 0 | U35: 0
A36: =B36&"-"&C36&"-"&D36&"-"&E36&"-"&F36&"-"&G36 -> 16384-1-16384-bf16-fp32-fp32 | B36: 16384 | C36: 1 | D36: 16384 | E36: bf16 | F36: fp32 | G36: fp32 | H36: 131072 | I36: 0 | J36: 0 | K36: 0 | L36: 64 | M36: 0 | N36: 70368744177664 | O36: 140763258159104 | P36: 18315.25 | Q36: 3842.08 | R36: 0 | S36: 0 | T36: 0 | U36: 0
A37: =B37&"-"&C37&"-"&D37&"-"&E37&"-"&F37&"-"&G37 -> 8192-1-8192-fp8-fp16-fp32 | B37: 8192 | C37: 1 | D37: 8192 | E37: fp8 | F37: fp16 | G37: fp32 | H37: 524288 | I37: 0 | J37: 0 | K37: 0 | L37: 64 | M37: 0 | N37: 70368744177664 | O37: 70394513981440 | P37: 54027.86 | Q37: 1302.45 | R37: 0 | S37: 0 | T37: 0 | U37: 0
A38: =B38&"-"&C38&"-"&D38&"-"&E38&"-"&F38&"-"&G38 -> 16384-1-16384-int8-int32-int32 | B38: 16384 | C38: 1 | D38: 16384 | E38: int8 | F38: int32 | G38: int32 | H38: 131072 | I38: 0 | J38: 0 | K38: 0 | L38: 64 | M38: 0 | N38: 70368744177664 | O38: 70390219014144 | P38: 45246.97 | Q38: 1555.21 | R38: 0 | S38: 0 | T38: 0 | U38: 0
A39: =B39&"-"&C39&"-"&D39&"-"&E39&"-"&F39&"-"&G39 -> 32768-1-32768-bf16-bf16-fp32 | B39: 32768 | C39: 1 | D39: 32768 | E39: bf16 | F39: bf16 | G39: fp32 | H39: 65536 | I39: 0 | J39: 0 | K39: 0 | L39: 64 | M39: 0 | N39: 140737488355328 | O39: 281492156579840 | P39: 29639.66 | Q39: 4748.28 | R39: 0 | S39: 0 | T39: 0 | U39: 0
A40: =B40&"-"&C40&"-"&D40&"-"&E40&"-"&F40&"-"&G40 -> 16384-1-16384-bf16-bf16-fp32 | B40: 16384 | C40: 1 | D40: 16384 | E40: bf16 | F40: bf16 | G40: fp32 | H40: 131072 | I40: 0 | J40: 0 | K40: 0 | L40: 64 | M40: 0 | N40: 70368744177664 | O40: 140754668224512 | P40: 20215.4 | Q40: 3480.95 | R40: 0 | S40: 0 | T40: 0 | U40: 0
A41: =B41&"-"&C41&"-"&D41&"-"&E41&"-"&F41&"-"&G41 -> 16384-1-16384-fp8-fp8-fp32 | B41: 16384 | C41: 1 | D41: 16384 | E41: fp8 | F41: fp8 | G41: fp32 | H41: 131072 | I41: 0 | J41: 0 | K41: 0 | L41: 64 | M41: 0 | N41: 70368744177664 | O41: 70377334112256 | P41: 54861.78 | Q41: 1282.66 | R41: 0 | S41: 0 | T41: 0 | U41: 0
A42: =B42&"-"&C42&"-"&D42&"-"&E42&"-"&F42&"-"&G42 -> 98304-1-98304-fp32-fp32-fp32 | B42: 98304 | C42: 1 | D42: 98304 | E42: fp32 | F42: fp32 | G42: fp32 | H42: 32768 | I42: 0 | J42: 0 | K42: 0 | L42: 64 | M42: 0 | N42: 633318697598976 | O42: 2.5333263e+15 | P42: 276949.34 | Q42: 2286.77 | R42: 0 | S42: 0 | T42: 0 | U42: 0
A43: =B43&"-"&C43&"-"&D43&"-"&E43&"-"&F43&"-"&G43 -> 8192-1-8192-fp16-fp16-fp16 | B43: 8192 | C43: 1 | D43: 8192 | E43: fp16 | F43: fp16 | G43: fp16
A44: =B44&"-"&C44&"-"&D44&"-"&E44&"-"&F44&"-"&G44 -> 8192-1-8192-bf16-fp32-fp32 | B44: 8192 | C44: 1 | D44: 8192 | E44: bf16 | F44: fp32 | G44: fp32 | H44: 524288 | I44: 0 | J44: 0 | K44: 0 | L44: 64 | M44: 0 | N44: 70368744177664 | O44: 140789027962880 | P44: 30353.79 | Q44: 2318.29 | R44: 0 | S44: 0 | T44: 0 | U44: 0
A45: =B45&"-"&C45&"-"&D45&"-"&E45&"-"&F45&"-"&G45 -> 98304-1-98304-fp8-fp8-fp32 | B45: 98304 | C45: 1 | D45: 98304 | E45: fp8 | F45: fp8 | G45: fp32 | H45: 32768 | I45: 0 | J45: 0 | K45: 0 | L45: 64 | M45: 0 | N45: 633318697598976 | O45: 633331582500864 | P45: 497263.78 | Q45: 1273.61 | R45: 0 | S45: 0 | T45: 0 | U45: 0
A46: =B46&"-"&C46&"-"&D46&"-"&E46&"-"&F46&"-"&G46 -> 4096-1-4096-bf8-bf8-fp32 | B46: 4096 | C46: 1 | D46: 4096 | E46: bf8 | F46: bf8 | G46: fp32 | H46: 524288 | I46: 0 | J46: 0 | K46: 0 | L46: 64 | M46: 0 | N46: 17592186044416 | O46: 17600775979008 | P46: 30893.08 | Q46: 569.45 | R46: 0 | S46: 0 | T46: 0 | U46: 0
A47: =B47&"-"&C47&"-"&D47&"-"&E47&"-"&F47&"-"&G47 -> 65536-1-65536-bf8-fp16-fp32 | B47: 65536 | C47: 1 | D47: 65536 | E47: bf8 | F47: fp16 | G47: fp32 | H47: 32768 | I47: 0 | J47: 0 | K47: 0 | L47: 64 | M47: 0 | N47: 281474976710656 | O47: 281487861612544 | P47: 198208.48 | Q47: 1420.1 | R47: 0 | S47: 0 | T47: 0 | U47: 0
A48: =B48&"-"&C48&"-"&D48&"-"&E48&"-"&F48&"-"&G48 -> 16384-1-16384-fp8-fp32-fp32 | B48: 16384 | C48: 1 | D48: 16384 | E48: fp8 | F48: fp32 | G48: fp32 | H48: 131072 | I48: 0 | J48: 0 | K48: 0 | L48: 64 | M48: 0 | N48: 70368744177664 | O48: 70390219014144 | P48: 54368.44 | Q48: 1294.29 | R48: 0 | S48: 0 | T48: 0 | U48: 0
A49: =B49&"-"&C49&"-"&D49&"-"&E49&"-"&F49&"-"&G49 -> 65536-1-65536-fp8-fp8-fp32 | B49: 65536 | C49: 1 | D49: 65536 | E49: fp8 | F49: fp8 | G49: fp32 | H49: 32768 | I49: 0 | J49: 0 | K49: 0 | L49: 64 | M49: 0 | N49: 281474976710656 | O49: 281483566645248 | P49: 198254.59 | Q49: 1419.77 | R49: 0 | S49: 0 | T49: 0 | U49: 0
A50: =B50&"-"&C50&"-"&D50&"-"&E50&"-"&F50&"-"&G50 -> 32768-1-32768-fp32-fp32-fp32 | B50: 32768 | C50: 1 | D50: 32768 | E50: fp32 | F50: fp32 | G50: fp32 | H50: 65536 | I50: 0 | J50: 0 | K50: 0 | L50: 64 | M50: 0 | N50: 140737488355328 | O50: 562984313159680 | P50: 76834.89 | Q50: 1831.69 | R50: 0 | S50: 0 | T50: 0 | U50: 0
A51: =B51&"-"&C51&"-"&D51&"-"&E51&"-"&F51&"-"&G51 -> 4096-1-4096-bf8-fp32-fp32 | B51: 4096 | C51: 1 | D51: 4096 | E51: bf8 | F51: fp32 | G51: fp32 | H51: 524288 | I51: 0 | J51: 0 | K51: 0 | L51: 64 | M51: 0 | N51: 17592186044416 | O51: 17613660880896 | P51: 21934.15 | Q51: 802.05 | R51: 0 | S51: 0 | T51: 0 | U51: 0
A52: =B52&"-"&C52&"-"&D52&"-"&E52&"-"&F52&"-"&G52 -> 98304-1-98304-bf8-fp32-fp32 | B52: 98304 | C52: 1 | D52: 98304 | E52: bf8 | F52: fp32 | G52: fp32 | H52: 32768 | I52: 0 | J52: 0 | K52: 0 | L52: 64 | M52: 0 | N52: 633318697598976 | O52: 633350909853696 | P52: 499635.06 | Q52: 1267.56 | R52: 0 | S52: 0 | T52: 0 | U52: 0
...

Sheet rocblas_mi300x_GF
B1: M | C1: N | D1: K | E1: mul | F1: acc | G1: scale | H1: n_iter | I1: n_thread | J1: n_wg | K1: n_wf | L1: wf_size | M1: wg_size | N1: n_flops | O1: n_bytes | P1: time_ms | Q1: gflop/s | R1: avg_clock | S1: max_clock | T1: min_clock | U1: stdev_clock
A2: =B2&"-"&C2&"-"&D2&"-"&E2&"-"&F2&"-"&G2 -> 8192-1-8192-int8-int32-int32 | B2: 8192 | C2: 1 | D2: 8192 | E2: int8 | F2: int32 | G2: int32 | H2: 524288 | I2: 0 | J2: 0 | K2: 0 | L2: 64 | M2: 0 | N2: 70368744177664 | O2: 70411693850624 | P2: 114240 | Q2: 615.971 | R2: 0 | S2: 0 | T2: 0 | U2: 0
A3: =B3&"-"&C3&"-"&D3&"-"&E3&"-"&F3&"-"&G3 -> 98304-1-98304-fp16-fp32-fp32 | B3: 98304 | C3: 1 | D3: 98304 | E3: fp16 | F3: fp32 | G3: fp32 | H3: 32768 | I3: 0 | J3: 0 | K3: 0 | L3: 64 | M3: 0 | N3: 633318697598976 | O3: 1.266676e+15 | P3: 197340 | Q3: 3209.27 | R3: 0 | S3: 0 | T3: 0 | U3: 0
A4: =B4&"-"&C4&"-"&D4&"-"&E4&"-"&F4&"-"&G4 -> 98304-1-98304-tf32-fp32-fp32 | B4: 98304 | C4: 1 | D4: 98304 | E4: tf32 | F4: fp32 | G4: fp32 | H4: 32768 | I4: 0 | J4: 0 | K4: 0 | L4: 64 | M4: 0 | N4: 633318697598976 | O4: 2.5333263e+15 | P4: 679952 | Q4: 931.417 | R4: 0 | S4: 0 | T4: 0 | U4: 0
A5: =B5&"-"&C5&"-"&D5&"-"&E5&"-"&F5&"-"&G5 -> 8192-1-8192-fp16-fp16-fp32 | B5: 8192 | C5: 1 | D5: 8192 | E5: fp16 | F5: fp16 | G5: fp32 | H5: 524288 | I5: 0 | J5: 0 | K5: 0 | L5: 64 | M5: 0 | N5: 70368744177664 | O5: 140771848093696 | P5: 145094 | Q5: 484.987 | R5: 0 | S5: 0 | T5: 0 | U5: 0
A6: =B6&"-"&C6&"-"&D6&"-"&E6&"-"&F6&"-"&G6 -> 32768-1-32768-int8-int32-int32 | B6: 32768 | C6: 1 | D6: 32768 | E6: int8 | F6: int32 | G6: int32 | H6: 65536 | I6: 0 | J6: 0 | K6: 0 | L6: 64 | M6: 0 | N6: 140737488355328 | O6: 140758963191808 | P6: 56317.6 | Q6: 2499 | R6: 0 | S6: 0 | T6: 0 | U6: 0
A7: =B7&"-"&C7&"-"&D7&"-"&E7&"-"&F7&"-"&G7 -> 32768-1-32768-bf8-fp32-fp32 | B7: 32768 | C7: 1 | D7: 32768 | E7: bf8 | F7: fp32 | G7: fp32
A8: =B8&"-"&C8&"-"&D8&"-"&E8&"-"&F8&"-"&G8 -> 65536-1-65536-fp16-fp32-fp32 | B8: 65536 | C8: 1 | D8: 65536 | E8: fp16 | F8: fp32 | G8: fp32 | H8: 32768 | I8: 0 | J8: 0 | K8: 0 | L8: 64 | M8: 0 | N8: 281474976710656 | O8: 562975723225088 | P8: 94441.5 | Q8: 2980.42 | R8: 0 | S8: 0 | T8: 0 | U8: 0
A9: =B9&"-"&C9&"-"&D9&"-"&E9&"-"&F9&"-"&G9 -> 8192-1-8192-bf8-fp32-fp32 | B9: 8192 | C9: 1 | D9: 8192 | E9: bf8 | F9: fp32 | G9: fp32
A10: =B10&"-"&C10&"-"&D10&"-"&E10&"-"&F10&"-"&G10 -> 65536-1-65536-bf16-fp32-fp32 | B10: 65536 | C10: 1 | D10: 65536 | E10: bf16 | F10: fp32 | G10: fp32 | H10: 32768 | I10: 0 | J10: 0 | K10: 0 | L10: 64 | M10: 0 | N10: 281474976710656 | O10: 562975723225088 | P10: 94977.9 | Q10: 2963.58 | R10: 0 | S10: 0 | T10: 0 | U10: 0
A11: =B11&"-"&C11&"-"&D11&"-"&E11&"-"&F11&"-"&G11 -> 65536-1-65536-bf16-bf16-fp32 | B11: 65536 | C11: 1 | D11: 65536 | E11: bf16 | F11: bf16 | G11: fp32 | H11: 32768 | I11: 0 | J11: 0 | K11: 0 | L11: 64 | M11: 0 | N11: 281474976710656 | O11: 562967133290496 | P11: 109588 | Q11: 2568.49 | R11: 0 | S11: 0 | T11: 0 | U11: 0
A12: =B12&"-"&C12&"-"&D12&"-"&E12&"-"&F12&"-"&G12 -> 32768-1-32768-bf16-fp32-fp32 | B12: 32768 | C12: 1 | D12: 32768 | E12: bf16 | F12: fp32 | G12: fp32 | H12: 65536 | I12: 0 | J12: 0 | K12: 0 | L12: 64 | M12: 0 | N12: 140737488355328 | O12: 281500746514432 | P12: 71780.9 | Q12: 1960.65 | R12: 0 | S12: 0 | T12: 0 | U12: 0
A13: =B13&"-"&C13&"-"&D13&"-"&E13&"-"&F13&"-"&G13 -> 16384-1-16384-fp32-fp32-fp32 | B13: 16384 | C13: 1 | D13: 16384 | E13: fp32 | F13: fp32 | G13: fp32 | H13: 131072 | I13: 0 | J13: 0 | K13: 0 | L13: 64 | M13: 0 | N13: 70368744177664 | O13: 281509336449024 | P13: 139350 | Q13: 504.977 | R13: 0 | S13: 0 | T13: 0 | U13: 0
A14: =B14&"-"&C14&"-"&D14&"-"&E14&"-"&F14&"-"&G14 -> 8192-1-8192-fp8-fp32-fp32 | B14: 8192 | C14: 1 | D14: 8192 | E14: fp8 | F14: fp32 | G14: fp32
A15: =B15&"-"&C15&"-"&D15&"-"&E15&"-"&F15&"-"&G15 -> 32768-1-32768-tf32-fp32-fp32 | B15: 32768 | C15: 1 | D15: 32768 | E15: tf32 | F15: fp32 | G15: fp32 | H15: 65536 | I15: 0 | J15: 0 | K15: 0 | L15: 64 | M15: 0 | N15: 140737488355328 | O15: 562984313159680 | P15: 149014 | Q15: 944.46 | R15: 0 | S15: 0 | T15: 0 | U15: 0
A16: =B16&"-"&C16&"-"&D16&"-"&E16&"-"&F16&"-"&G16 -> 65536-1-65536-fp8-fp32-fp32 | B16: 65536 | C16: 1 | D16: 65536 | E16: fp8 | F16: fp32 | G16: fp32
A17: =B17&"-"&C17&"-"&D17&"-"&E17&"-"&F17&"-"&G17 -> 16384-1-16384-fp16-fp32-fp32 | B17: 16384 | C17: 1 | D17: 16384 | E17: fp16 | F17: fp32 | G17: fp32 | H17: 131072 | I17: 0 | J17: 0 | K17: 0 | L17: 64 | M17: 0 | N17: 70368744177664 | O17: 140763258159104 | P17: 72425.1 | Q17: 971.607 | R17: 0 | S17: 0 | T17: 0 | U17: 0
A18: =B18&"-"&C18&"-"&D18&"-"&E18&"-"&F18&"-"&G18 -> 98304-1-98304-fp32-fp32-fp32 | B18: 98304 | C18: 1 | D18: 98304 | E18: fp32 | F18: fp32 | G18: fp32 | H18: 32768 | I18: 0 | J18: 0 | K18: 0 | L18: 64 | M18: 0 | N18: 633318697598976 | O18: 2.5333263e+15 | P18: 683148 | Q18: 927.059 | R18: 0 | S18: 0 | T18: 0 | U18: 0
A19: =B19&"-"&C19&"-"&D19&"-"&E19&"-"&F19&"-"&G19 -> 32768-1-32768-bf16-bf16-fp32 | B19: 32768 | C19: 1 | D19: 32768 | E19: bf16 | F19: bf16 | G19: fp32 | H19: 65536 | I19: 0 | J19: 0 | K19: 0 | L19: 64 | M19: 0 | N19: 140737488355328 | O19: 281492156579840 | P19: 77409.3 | Q19: 1818.1 | R19: 0 | S19: 0 | T19: 0 | U19: 0
A20: =B20&"-"&C20&"-"&D20&"-"&E20&"-"&F20&"-"&G20 -> 8192-1-8192-fp32-fp32-fp32 | B20: 8192 | C20: 1 | D20: 8192 | E20: fp32 | F20: fp32 | G20: fp32 | H20: 524288 | I20: 0 | J20: 0 | K20: 0 | L20: 64 | M20: 0 | N20: 70368744177664 | O20: 281543696187392 | P20: 286065 | Q20: 245.989 | R20: 0 | S20: 0 | T20: 0 | U20: 0
A21: =B21&"-"&C21&"-"&D21&"-"&E21&"-"&F21&"-"&G21 -> 4096-1-4096-fp64-fp64-fp64 | B21: 4096 | C21: 1 | D21: 4096 | E21: fp64 | F21: fp64 | G21: fp64 | H21: 524288 | I21: 0 | J21: 0 | K21: 0 | L21: 64 | M21: 0 | N21: 17592186044416 | O21: 140806207832064 | P21: 29408.4 | Q21: 598.203 | R21: 0 | S21: 0 | T21: 0 | U21: 0
A22: =B22&"-"&C22&"-"&D22&"-"&E22&"-"&F22&"-"&G22 -> 16384-1-16384-fp16-fp16-fp32 | B22: 16384 | C22: 1 | D22: 16384 | E22: fp16 | F22: fp16 | G22: fp32 | H22: 131072 | I22: 0 | J22: 0 | K22: 0 | L22: 64 | M22: 0 | N22: 70368744177664 | O22: 140754668224512 | P22: 76348.1 | Q22: 921.683 | R22: 0 | S22: 0 | T22: 0 | U22: 0
A23: =B23&"-"&C23&"-"&D23&"-"&E23&"-"&F23&"-"&G23 -> 16384-1-16384-bf16-fp32-fp32 | B23: 16384 | C23: 1 | D23: 16384 | E23: bf16 | F23: fp32 | G23: fp32 | H23: 131072 | I23: 0 | J23: 0 | K23: 0 | L23: 64 | M23: 0 | N23: 70368744177664 | O23: 140763258159104 | P23: 72368.7 | Q23: 972.365 | R23: 0 | S23: 0 | T23: 0 | U23: 0
A24: =B24&"-"&C24&"-"&D24&"-"&E24&"-"&F24&"-"&G24 -> 4096-1-4096-fp16-fp16-fp32 | B24: 4096 | C24: 1 | D24: 4096 | E24: fp16 | F24: fp16 | G24: fp32 | H24: 524288 | I24: 0 | J24: 0 | K24: 0 | L24: 64 | M24: 0 | N24: 17592186044416 | O24: 35201551958016 | P24: 29004.1 | Q24: 606.541 | R24: 0 | S24: 0 | T24: 0 | U24: 0
A25: =B25&"-"&C25&"-"&D25&"-"&E25&"-"&F25&"-"&G25 -> 98304-1-98304-fp64-fp64-fp64 | B25: 98304 | C25: 1 | D25: 98304 | E25: fp64 | F25: fp64 | G25: fp64 | H25: 32768 | I25: 0 | J25: 0 | K25: 0 | L25: 64 | M25: 0 | N25: 633318697598976 | O25: 5.0666527e+15 | P25: 524134 | Q25: 1208.32 | R25: 0 | S25: 0 | T25: 0 | U25: 0
A26: =B26&"-"&C26&"-"&D26&"-"&E26&"-"&F26&"-"&G26 -> 16384-1-16384-fp16-fp16-fp16 | B26: 16384 | C26: 1 | D26: 16384 | E26: fp16 | F26: fp16 | G26: fp16 | H26: 131072 | I26: 0 | J26: 0 | K26: 0 | L26: 64 | M26: 0 | N26: 70368744177664 | O26: 140754668224512 | P26: 57287 | Q26: 1228.35 | R26: 0 | S26: 0 | T26: 0 | U26: 0
A27: =B27&"-"&C27&"-"&D27&"-"&E27&"-"&F27&"-"&G27 -> 98304-1-98304-int8-int32-int32 | B27: 98304 | C27: 1 | D27: 98304 | E27: int8 | F27: int32 | G27: int32 | H27: 32768 | I27: 0 | J27: 0 | K27: 0 | L27: 64 | M27: 0 | N27: 633318697598976 | O27: 633350909853696 | P27: 198312 | Q27: 3193.55 | R27: 0 | S27: 0 | T27: 0 | U27: 0
A28: =B28&"-"&C28&"-"&D28&"-"&E28&"-"&F28&"-"&G28 -> 32768-1-32768-fp64-fp64-fp64 | B28: 32768 | C28: 1 | D28: 32768 | E28: fp64 | F28: fp64 | G28: fp64 | H28: 65536 | I28: 0 | J28: 0 | K28: 0 | L28: 64 | M28: 0 | N28: 140737488355328 | O28: 1.1259686e+15 | P28: 123548 | Q28: 1139.13 | R28: 0 | S28: 0 | T28: 0 | U28: 0
A29: =B29&"-"&C29&"-"&D29&"-"&E29&"-"&F29&"-"&G29 -> 4096-1-4096-fp16-fp16-fp16 | B29: 4096 | C29: 1 | D29: 4096 | E29: fp16 | F29: fp16 | G29: fp16 | H29: 524288 | I29: 0 | J29: 0 | K29: 0 | L29: 64 | M29: 0 | N29: 17592186044416 | O29: 35201551958016 | P29: 66876.1 | Q29: 263.056 | R29: 0 | S29: 0 | T29: 0 | U29: 0
A30: =B30&"-"&C30&"-"&D30&"-"&E30&"-"&F30&"-"&G30 -> 16384-1-16384-bf8-fp32-fp32 | B30: 16384 | C30: 1 | D30: 16384 | E30: bf8 | F30: fp32 | G30: fp32
A31: =B31&"-"&C31&"-"&D31&"-"&E31&"-"&F31&"-"&G31 -> 65536-1-65536-bf8-fp32-fp32 | B31: 65536 | C31: 1 | D31: 65536 | E31: bf8 | F31: fp32 | G31: fp32
A32: =B32&"-"&C32&"-"&D32&"-"&E32&"-"&F32&"-"&G32 -> 65536-1-65536-fp32-fp32-fp32 | B32: 65536 | C32: 1 | D32: 65536 | E32: fp32 | F32: fp32 | G32: fp32 | H32: 32768 | I32: 0 | J32: 0 | K32: 0 | L32: 64 | M32: 0 | N32: 281474976710656 | O32: 1.1259343e+15 | P32: 295156 | Q32: 953.647 | R32: 0 | S32: 0 | T32: 0 | U32: 0
A33: =B33&"-"&C33&"-"&D33&"-"&E33&"-"&F33&"-"&G33 -> 32768-1-32768-fp16-fp16-fp16 | B33: 32768 | C33: 1 | D33: 32768 | E33: fp16 | F33: fp16 | G33: fp16 | H33: 65536 | I33: 0 | J33: 0 | K33: 0 | L33: 64 | M33: 0 | N33: 140737488355328 | O33: 281492156579840 | P33: 103694 | Q33: 1357.23 | R33: 0 | S33: 0 | T33: 0 | U33: 0
A34: =B34&"-"&C34&"-"&D34&"-"&E34&"-"&F34&"-"&G34 -> 4096-1-4096-bf16-bf16-fp32 | B34: 4096 | C34: 1 | D34: 4096 | E34: bf16 | F34: bf16 | G34: fp32 | H34: 524288 | I34: 0 | J34: 0 | K34: 0 | L34: 64 | M34: 0 | N34: 17592186044416 | O34: 35201551958016 | P34: 29070.7 | Q34: 605.152 | R34: 0 | S34: 0 | T34: 0 | U34: 0
A35: =B35&"-"&C35&"-"&D35&"-"&E35&"-"&F35&"-"&G35 -> 98304-1-98304-bf16-fp32-fp32 | B35: 98304 | C35: 1 | D35: 98304 | E35: bf16 | F35: fp32 | G35: fp32 | H35: 32768 | I35: 0 | J35: 0 | K35: 0 | L35: 64 | M35: 0 | N35: 633318697598976 | O35: 1.266676e+15 | P35: 196599 | Q35: 3221.37 | R35: 0 | S35: 0 | T35: 0 | U35: 0
A36: =B36&"-"&C36&"-"&D36&"-"&E36&"-"&F36&"-"&G36 -> 32768-1-32768-fp8-fp32-fp32 | B36: 32768 | C36: 1 | D36: 32768 | E36: fp8 | F36: fp32 | G36: fp32
A37: =B37&"-"&C37&"-"&D37&"-"&E37&"-"&F37&"-"&G37 -> 65536-1-65536-int8-int32-int32 | B37: 65536 | C37: 1 | D37: 65536 | E37: int8 | F37: int32 | G37: int32 | H37: 32768 | I37: 0 | J37: 0 | K37: 0 | L37: 64 | M37: 0 | N37: 281474976710656 | O37: 281496451547136 | P37: 66943.4 | Q37: 4204.67 | R37: 0 | S37: 0 | T37: 0 | U37: 0
A38: =B38&"-"&C38&"-"&D38&"-"&E38&"-"&F38&"-"&G38 -> 8192-1-8192-fp16-fp32-fp32 | B38: 8192 | C38: 1 | D38: 8192 | E38: fp16 | F38: fp32 | G38: fp32 | H38: 524288 | I38: 0 | J38: 0 | K38: 0 | L38: 64 | M38: 0 | N38: 70368744177664 | O38: 140789027962880 | P38: 167476 | Q38: 420.172 | R38: 0 | S38: 0 | T38: 0 | U38: 0
A39: =B39&"-"&C39&"-"&D39&"-"&E39&"-"&F39&"-"&G39 -> 32768-1-32768-fp16-fp16-fp32 | B39: 32768 | C39: 1 | D39: 32768 | E39: fp16 | F39: fp16 | G39: fp32 | H39: 65536 | I39: 0 | J39: 0 | K39: 0 | L39: 64 | M39: 0 | N39: 140737488355328 | O39: 281492156579840 | P39: 78179.2 | Q39: 1800.19 | R39: 0 | S39: 0 | T39: 0 | U39: 0
A40: =B40&"-"&C40&"-"&D40&"-"&E40&"-"&F40&"-"&G40 -> 98304-1-98304-bf8-fp32-fp32 | B40: 98304 | C40: 1 | D40: 98304 | E40: bf8 | F40: fp32 | G40: fp32
...

Sheet rocblas_mi325x_750W_Auto_GF
B1: M | C1: N | D1: K | E1: mul | F1: acc | G1: scale | H1: n_iter | I1: n_thread | J1: n_wg | K1: n_wf | L1: wf_size | M1: wg_size | N1: n_flops | O1: n_bytes | P1: time_ms | Q1: gflop/s | R1: avg_clock | S1: max_clock | T1: min_clock | U1: stdev_clock
A2: =B2&"-"&C2&"-"&D2&"-"&E2&"-"&F2&"-"&G2 -> 8192-1-8192-int8-int32-int32 | B2: 8192 | C2: 1 | D2: 8192 | E2: int8 | F2: int32 | G2: int32 | H2: 524288 | I2: 0 | J2: 0 | K2: 0 | L2: 64 | M2: 0 | N2: 70368744177664 | O2: 70411693850624 | P2: 110968 | Q2: 634.133 | R2: 0 | S2: 0 | T2: 0 | U2: 0
A3: =B3&"-"&C3&"-"&D3&"-"&E3&"-"&F3&"-"&G3 -> 98304-1-98304-fp16-fp32-fp32 | B3: 98304 | C3: 1 | D3: 98304 | E3: fp16 | F3: fp32 | G3: fp32 | H3: 32768 | I3: 0 | J3: 0 | K3: 0 | L3: 64 | M3: 0 | N3: 633318697598976 | O3: 1.266676e+15 | P3: 189541 | Q3: 3341.33 | R3: 0 | S3: 0 | T3: 0 | U3: 0
